<mujoco model="stiff-rope">
  <worldbody>
    <body name="stiffrope" pos="0.3 0.0 0.5" quat="0.0 0.0 1.0 0.0">
      <site name="ft_rope" pos="0 0 0" size="0.01 0.01 0.01" rgba="1 0 0 0" type="sphere" group="1" />
      <body name="B_first">
        <site name="S_first" pos="0 0 0" size="0.009000000000000001"/>
        <geom name="G0" pos="0.02 0 0" quat="0.707107 0 -0.707107 0" type="capsule" size="0.0100 0.0200" rgba="0.1 0.05333333333333334 0.6733333333333333 1.0" conaffinity="0" contype="0" solref="0.001 1" condim="1"/>
        <site name="S_0" pos="0 0 0" size="0.009000000000000001" rgba="0 0 0 0"/>
        <site name="twistcylx_1" pos="0 0 0.05" quat="0.707 0 0 -0.707" size="0.001 0.05" rgba="0 0 1 0.0" type="cylinder" group="1" />
        <site name="twistcyly_1" pos="0 0.05 0" quat="0.707 -0.707 0 0" size="0.001 0.05" rgba="1 1 0 0.0" type="cylinder" group="1" />
        <body name="B_1" pos="0.04 0 0">
          <joint name="J_1" type="ball" pos="0 0 0" stiffness="0.0" damping="0.5" actuatorfrclimited="false"/>
          <geom name="G1" pos="0.02 0 0" quat="0.707107 0 -0.707107 0" type="capsule" size="0.0100 0.0200" rgba="0.1 0.05333333333333334 0.6733333333333333 1.0" conaffinity="0" contype="0" solref="0.001 1" condim="1"/>
          <site name="S_1" pos="0 0 0" size="0.009000000000000001" rgba="0 0 0 0"/>
          <body name="B_2" pos="0.04 0 0">
            <joint name="J_2" type="ball" pos="0 0 0" stiffness="0.0" damping="0.5" actuatorfrclimited="false"/>
            <geom name="G2" pos="0.02 0 0" quat="0.707107 0 -0.707107 0" type="capsule" size="0.0100 0.0200" rgba="0.1 0.05333333333333334 0.6733333333333333 1.0" conaffinity="0" contype="0" solref="0.001 1" condim="1"/>
            <site name="S_2" pos="0 0 0" size="0.009000000000000001" rgba="0 0 0 0"/>
            <body name="B_3" pos="0.04 0 0">
              <joint name="J_3" type="ball" pos="0 0 0" stiffness="0.0" damping="0.5" actuatorfrclimited="false"/>
              <geom name="G3" pos="0.02 0 0" quat="0.707107 0 -0.707107 0" type="capsule" size="0.0100 0.0200" rgba="0.1 0.05333333333333334 0.6733333333333333 1.0" conaffinity="0" contype="0" solref="0.001 1" condim="1"/>
              <site name="S_3" pos="0 0 0" size="0.009000000000000001" rgba="0 0 0 0"/>
              <body name="B_4" pos="0.04 0 0">
                <joint name="J_4" type="ball" pos="0 0 0" stiffness="0.0" damping="0.5" actuatorfrclimited="false"/>
                <geom name="G4" pos="0.02 0 0" quat="0.707107 0 -0.707107 0" type="capsule" size="0.0100 0.0200" rgba="0.1 0.05333333333333334 0.6733333333333333 1.0" conaffinity="0" contype="0" solref="0.001 1" condim="1"/>
                <site name="S_4" pos="0 0 0" size="0.009000000000000001" rgba="0 0 0 0"/>
                <body name="B_5" pos="0.04 0 0">
                  <joint name="J_5" type="ball" pos="0 0 0" stiffness="0.0" damping="0.5" actuatorfrclimited="false"/>
                  <geom name="G5" pos="0.02 0 0" quat="0.707107 0 -0.707107 0" type="capsule" size="0.0100 0.0200" rgba="0.1 0.05333333333333334 0.6733333333333333 1.0" conaffinity="0" contype="0" solref="0.001 1" condim="1"/>
                  <site name="S_5" pos="0 0 0" size="0.009000000000000001" rgba="0 0 0 0"/>
                  <body name="B_6" pos="0.04 0 0">
                    <joint name="J_6" type="ball" pos="0 0 0" stiffness="0.0" damping="0.5" actuatorfrclimited="false"/>
                    <geom name="G6" pos="0.02 0 0" quat="0.707107 0 -0.707107 0" type="capsule" size="0.0100 0.0200" rgba="0.1 0.05333333333333334 0.6733333333333333 1.0" conaffinity="0" contype="0" solref="0.001 1" condim="1"/>
                    <site name="S_6" pos="0 0 0" size="0.009000000000000001" rgba="0 0 0 0"/>
                    <body name="B_7" pos="0.04 0 0">
                      <joint name="J_7" type="ball" pos="0 0 0" stiffness="0.0" damping="0.5" actuatorfrclimited="false"/>
                      <geom name="G7" pos="0.02 0 0" quat="0.707107 0 -0.707107 0" type="capsule" size="0.0100 0.0200" rgba="0.1 0.05333333333333334 0.6733333333333333 1.0" conaffinity="0" contype="0" solref="0.001 1" condim="1"/>
                      <site name="S_7" pos="0 0 0" size="0.009000000000000001" rgba="0 0 0 0"/>
                      <site name="twistcylx_8" pos="0 0 0.05" quat="0.707 0 0 -0.707" size="0.001 0.05" rgba="0 0 1 0.0" type="cylinder" group="1" />
                      <site name="twistcyly_8" pos="0 0.05 0" quat="0.707 -0.707 0 0" size="0.001 0.05" rgba="1 1 0 0.0" type="cylinder" group="1" />
                      <body name="B_8" pos="0.04 0 0">
                        <joint name="J_8" type="ball" pos="0 0 0" stiffness="0.0" damping="0.5" actuatorfrclimited="false"/>
                        <geom name="G8" pos="0.02 0 0" quat="0.707107 0 -0.707107 0" type="capsule" size="0.0100 0.0200" rgba="0.1 0.05333333333333334 0.6733333333333333 1.0" conaffinity="0" contype="0" solref="0.001 1" condim="1"/>
                        <site name="S_8" pos="0 0 0" size="0.009000000000000001" rgba="0 0 0 0"/>
                        <body name="B_9" pos="0.04 0 0">
                          <joint name="J_9" type="ball" pos="0 0 0" stiffness="0.0" damping="0.5" actuatorfrclimited="false"/>
                          <geom name="G9" pos="0.02 0 0" quat="0.707107 0 -0.707107 0" type="capsule" size="0.0100 0.0200" rgba="0.1 0.05333333333333334 0.6733333333333333 1.0" conaffinity="0" contype="0" solref="0.001 1" condim="1"/>
                          <site name="S_9" pos="0 0 0" size="0.009000000000000001" rgba="0 0 0 0"/>
                          <body name="B_10" pos="0.04 0 0">
                            <joint name="J_10" type="ball" pos="0 0 0" stiffness="0.0" damping="0.5" actuatorfrclimited="false"/>
                            <geom name="G10" pos="0.02 0 0" quat="0.707107 0 -0.707107 0" type="capsule" size="0.0100 0.0200" rgba="0.1 0.05333333333333334 0.6733333333333333 1.0" conaffinity="0" contype="0" solref="0.001 1" condim="1"/>
                            <site name="S_10" pos="0 0 0" size="0.009000000000000001" rgba="0 0 0 0"/>
                            <body name="B_11" pos="0.04 0 0">
                              <joint name="J_11" type="ball" pos="0 0 0" stiffness="0.0" damping="0.5" actuatorfrclimited="false"/>
                              <geom name="G11" pos="0.02 0 0" quat="0.707107 0 -0.707107 0" type="capsule" size="0.0100 0.0200" rgba="0.1 0.05333333333333334 0.6733333333333333 1.0" conaffinity="0" contype="0" solref="0.001 1" condim="1"/>
                              <site name="S_11" pos="0 0 0" size="0.009000000000000001" rgba="0 0 0 0"/>
                              <body name="B_12" pos="0.04 0 0">
                                <joint name="J_12" type="ball" pos="0 0 0" stiffness="0.0" damping="0.5" actuatorfrclimited="false"/>
                                <geom name="G12" pos="0.02 0 0" quat="0.707107 0 -0.707107 0" type="capsule" size="0.0100 0.0200" rgba="0.1 0.05333333333333334 0.6733333333333333 1.0" conaffinity="0" contype="0" solref="0.001 1" condim="1"/>
                                <site name="S_12" pos="0 0 0" size="0.009000000000000001" rgba="0 0 0 0"/>
                                <body name="B_13" pos="0.04 0 0">
                                  <joint name="J_13" type="ball" pos="0 0 0" stiffness="0.0" damping="0.5" actuatorfrclimited="false"/>
                                  <geom name="G13" pos="0.02 0 0" quat="0.707107 0 -0.707107 0" type="capsule" size="0.0100 0.0200" rgba="0.1 0.05333333333333334 0.6733333333333333 1.0" conaffinity="0" contype="0" solref="0.001 1" condim="1"/>
                                  <site name="S_13" pos="0 0 0" size="0.009000000000000001" rgba="0 0 0 0"/>
                                  <body name="B_last" pos="0.04 0 0">
                                    <joint name="J_last" type="ball" pos="0 0 0" stiffness="0.0" damping="0.5" actuatorfrclimited="false"/>
                                    <geom name="G14" pos="0.02 0 0" quat="0.707107 0 -0.707107 0" type="capsule" size="0.0100 0.0200" rgba="0.1 0.05333333333333334 0.6733333333333333 1.0" conaffinity="0" contype="0" solref="0.001 1" condim="1"/>
                                    <site name="S_14" pos="0 0 0" size="0.009000000000000001" rgba="0 0 0 0"/>
                                    <site name="twistcylx_15" pos="0 0 0.05" quat="0.707 0 0 -0.707" size="0.001 0.05" rgba="0 0 1 0.0" type="cylinder" group="1" />
                                    <site name="twistcyly_15" pos="0 0.05 0" quat="0.707 -0.707 0 0" size="0.001 0.05" rgba="1 1 0 0.0" type="cylinder" group="1" />
                                    <site name="S_last" pos="0.04 0 0" size="0.009000000000000001"/>
                                    <body name="B_last2" pos="0.04 0 0">
                                    </body>
                                  </body>
                                </body>
                              </body>
                            </body>
                          </body>
                        </body>
                      </body>
                    </body>
                  </body>
                </body>
              </body>
            </body>
          </body>
        </body>
      </body>
    </body>
  </worldbody>
  <sensor>
  </sensor>
  <equality>
    <weld body1='B_last' body2='eef_body' solref='0.001 1'/>
  </equality>
  <contact>
    <exclude body1="B_first" body2="B_1"/>
    <exclude body1="B_first" body2="B_last"/>
    <exclude body1="B_1" body2="B_last"/>
    <exclude body1="B_first" body2="B_13"/>
    <exclude body1="eef_body" body2="B_first"/>
    <exclude body1="eef_body" body2="B_last"/>
    <exclude body1="eef_body" body2="B_13"/>
  </contact>
</mujoco>
