<mujoco model="stiff-rope">
  <worldbody>
    <body name="stiffrope" pos="4.645 0.0 0.5" quat="0.0 0.0 1.0 0.0">
      <freejoint name="freejoint_A"/>
      <site name="ft_rope" pos="0 0 0" size="0.03 0.015 0.015" rgba="1 0 0 0" type="sphere" group="1" />
      <body name="B_first">
        <site name="S_first" pos="0 0 0" size="0.0135"/>
        <geom name="G0" pos="0.058062499999999996 0 0" quat="0.707107 0 -0.707107 0" type="capsule" size="0.0150 0.0581" rgba="0.1 0.05333333333333334 0.6733333333333333 1" conaffinity="0" contype="0" solref="0.001 1" condim="1"/>
        <site name="S_0" pos="0 0 0" size="0.0135" rgba="0 0 0 0"/>
        <site name="twistcylx_1" pos="0 0 0.05" quat="0.707 0 0 -0.707" size="0.001 0.05" rgba="0 0 1 0.0" type="cylinder" group="1" />
        <site name="twistcyly_1" pos="0 0.05 0" quat="0.707 -0.707 0 0" size="0.001 0.05" rgba="1 1 0 0.0" type="cylinder" group="1" />
        <body name="B_1" pos="0.11612499999999999 0 0">
          <joint name="J_1" type="ball" pos="0 0 0" stiffness="0.0" damping="1.0" actuatorfrclimited="false"/>
          <geom name="G1" pos="0.058062499999999996 0 0" quat="0.707107 0 -0.707107 0" type="capsule" size="0.0150 0.0581" rgba="0.1 0.05333333333333334 0.6733333333333333 1" conaffinity="0" contype="0" solref="0.001 1" condim="1"/>
          <site name="S_1" pos="0 0 0" size="0.0135" rgba="0 0 0 0"/>
          <body name="B_2" pos="0.11612499999999999 0 0">
            <joint name="J_2" type="ball" pos="0 0 0" stiffness="0.0" damping="1.0" actuatorfrclimited="false"/>
            <geom name="G2" pos="0.058062499999999996 0 0" quat="0.707107 0 -0.707107 0" type="capsule" size="0.0150 0.0581" rgba="0.1 0.05333333333333334 0.6733333333333333 1" conaffinity="0" contype="0" solref="0.001 1" condim="1"/>
            <site name="S_2" pos="0 0 0" size="0.0135" rgba="0 0 0 0"/>
            <body name="B_3" pos="0.11612499999999999 0 0">
              <joint name="J_3" type="ball" pos="0 0 0" stiffness="0.0" damping="1.0" actuatorfrclimited="false"/>
              <geom name="G3" pos="0.058062499999999996 0 0" quat="0.707107 0 -0.707107 0" type="capsule" size="0.0150 0.0581" rgba="0.1 0.05333333333333334 0.6733333333333333 1" conaffinity="0" contype="0" solref="0.001 1" condim="1"/>
              <site name="S_3" pos="0 0 0" size="0.0135" rgba="0 0 0 0"/>
              <body name="B_4" pos="0.11612499999999999 0 0">
                <joint name="J_4" type="ball" pos="0 0 0" stiffness="0.0" damping="1.0" actuatorfrclimited="false"/>
                <geom name="G4" pos="0.058062499999999996 0 0" quat="0.707107 0 -0.707107 0" type="capsule" size="0.0150 0.0581" rgba="0.1 0.05333333333333334 0.6733333333333333 1" conaffinity="0" contype="0" solref="0.001 1" condim="1"/>
                <site name="S_4" pos="0 0 0" size="0.0135" rgba="0 0 0 0"/>
                <body name="B_5" pos="0.11612499999999999 0 0">
                  <joint name="J_5" type="ball" pos="0 0 0" stiffness="0.0" damping="1.0" actuatorfrclimited="false"/>
                  <geom name="G5" pos="0.058062499999999996 0 0" quat="0.707107 0 -0.707107 0" type="capsule" size="0.0150 0.0581" rgba="0.1 0.05333333333333334 0.6733333333333333 1" conaffinity="0" contype="0" solref="0.001 1" condim="1"/>
                  <site name="S_5" pos="0 0 0" size="0.0135" rgba="0 0 0 0"/>
                  <body name="B_6" pos="0.11612499999999999 0 0">
                    <joint name="J_6" type="ball" pos="0 0 0" stiffness="0.0" damping="1.0" actuatorfrclimited="false"/>
                    <geom name="G6" pos="0.058062499999999996 0 0" quat="0.707107 0 -0.707107 0" type="capsule" size="0.0150 0.0581" rgba="0.1 0.05333333333333334 0.6733333333333333 1" conaffinity="0" contype="0" solref="0.001 1" condim="1"/>
                    <site name="S_6" pos="0 0 0" size="0.0135" rgba="0 0 0 0"/>
                    <body name="B_7" pos="0.11612499999999999 0 0">
                      <joint name="J_7" type="ball" pos="0 0 0" stiffness="0.0" damping="1.0" actuatorfrclimited="false"/>
                      <geom name="G7" pos="0.058062499999999996 0 0" quat="0.707107 0 -0.707107 0" type="capsule" size="0.0150 0.0581" rgba="0.1 0.05333333333333334 0.6733333333333333 1" conaffinity="0" contype="0" solref="0.001 1" condim="1"/>
                      <site name="S_7" pos="0 0 0" size="0.0135" rgba="0 0 0 0"/>
                      <body name="B_8" pos="0.11612499999999999 0 0">
                        <joint name="J_8" type="ball" pos="0 0 0" stiffness="0.0" damping="1.0" actuatorfrclimited="false"/>
                        <geom name="G8" pos="0.058062499999999996 0 0" quat="0.707107 0 -0.707107 0" type="capsule" size="0.0150 0.0581" rgba="0.1 0.05333333333333334 0.6733333333333333 1" conaffinity="0" contype="0" solref="0.001 1" condim="1"/>
                        <site name="S_8" pos="0 0 0" size="0.0135" rgba="0 0 0 0"/>
                        <body name="B_9" pos="0.11612499999999999 0 0">
                          <joint name="J_9" type="ball" pos="0 0 0" stiffness="0.0" damping="1.0" actuatorfrclimited="false"/>
                          <geom name="G9" pos="0.058062499999999996 0 0" quat="0.707107 0 -0.707107 0" type="capsule" size="0.0150 0.0581" rgba="0.1 0.05333333333333334 0.6733333333333333 1" conaffinity="0" contype="0" solref="0.001 1" condim="1"/>
                          <site name="S_9" pos="0 0 0" size="0.0135" rgba="0 0 0 0"/>
                          <body name="B_10" pos="0.11612499999999999 0 0">
                            <joint name="J_10" type="ball" pos="0 0 0" stiffness="0.0" damping="1.0" actuatorfrclimited="false"/>
                            <geom name="G10" pos="0.058062499999999996 0 0" quat="0.707107 0 -0.707107 0" type="capsule" size="0.0150 0.0581" rgba="0.1 0.05333333333333334 0.6733333333333333 1" conaffinity="0" contype="0" solref="0.001 1" condim="1"/>
                            <site name="S_10" pos="0 0 0" size="0.0135" rgba="0 0 0 0"/>
                            <body name="B_11" pos="0.11612499999999999 0 0">
                              <joint name="J_11" type="ball" pos="0 0 0" stiffness="0.0" damping="1.0" actuatorfrclimited="false"/>
                              <geom name="G11" pos="0.058062499999999996 0 0" quat="0.707107 0 -0.707107 0" type="capsule" size="0.0150 0.0581" rgba="0.1 0.05333333333333334 0.6733333333333333 1" conaffinity="0" contype="0" solref="0.001 1" condim="1"/>
                              <site name="S_11" pos="0 0 0" size="0.0135" rgba="0 0 0 0"/>
                              <body name="B_12" pos="0.11612499999999999 0 0">
                                <joint name="J_12" type="ball" pos="0 0 0" stiffness="0.0" damping="1.0" actuatorfrclimited="false"/>
                                <geom name="G12" pos="0.058062499999999996 0 0" quat="0.707107 0 -0.707107 0" type="capsule" size="0.0150 0.0581" rgba="0.1 0.05333333333333334 0.6733333333333333 1" conaffinity="0" contype="0" solref="0.001 1" condim="1"/>
                                <site name="S_12" pos="0 0 0" size="0.0135" rgba="0 0 0 0"/>
                                <body name="B_13" pos="0.11612499999999999 0 0">
                                  <joint name="J_13" type="ball" pos="0 0 0" stiffness="0.0" damping="1.0" actuatorfrclimited="false"/>
                                  <geom name="G13" pos="0.058062499999999996 0 0" quat="0.707107 0 -0.707107 0" type="capsule" size="0.0150 0.0581" rgba="0.1 0.05333333333333334 0.6733333333333333 1" conaffinity="0" contype="0" solref="0.001 1" condim="1"/>
                                  <site name="S_13" pos="0 0 0" size="0.0135" rgba="0 0 0 0"/>
                                  <body name="B_14" pos="0.11612499999999999 0 0">
                                    <joint name="J_14" type="ball" pos="0 0 0" stiffness="0.0" damping="1.0" actuatorfrclimited="false"/>
                                    <geom name="G14" pos="0.058062499999999996 0 0" quat="0.707107 0 -0.707107 0" type="capsule" size="0.0150 0.0581" rgba="0.1 0.05333333333333334 0.6733333333333333 1" conaffinity="0" contype="0" solref="0.001 1" condim="1"/>
                                    <site name="S_14" pos="0 0 0" size="0.0135" rgba="0 0 0 0"/>
                                    <body name="B_15" pos="0.11612499999999999 0 0">
                                      <joint name="J_15" type="ball" pos="0 0 0" stiffness="0.0" damping="1.0" actuatorfrclimited="false"/>
                                      <geom name="G15" pos="0.058062499999999996 0 0" quat="0.707107 0 -0.707107 0" type="capsule" size="0.0150 0.0581" rgba="0.1 0.05333333333333334 0.6733333333333333 1" conaffinity="0" contype="0" solref="0.001 1" condim="1"/>
                                      <site name="S_15" pos="0 0 0" size="0.0135" rgba="0 0 0 0"/>
                                      <body name="B_16" pos="0.11612499999999999 0 0">
                                        <joint name="J_16" type="ball" pos="0 0 0" stiffness="0.0" damping="1.0" actuatorfrclimited="false"/>
                                        <geom name="G16" pos="0.058062499999999996 0 0" quat="0.707107 0 -0.707107 0" type="capsule" size="0.0150 0.0581" rgba="0.1 0.05333333333333334 0.6733333333333333 1" conaffinity="0" contype="0" solref="0.001 1" condim="1"/>
                                        <site name="S_16" pos="0 0 0" size="0.0135" rgba="0 0 0 0"/>
                                        <body name="B_17" pos="0.11612499999999999 0 0">
                                          <joint name="J_17" type="ball" pos="0 0 0" stiffness="0.0" damping="1.0" actuatorfrclimited="false"/>
                                          <geom name="G17" pos="0.058062499999999996 0 0" quat="0.707107 0 -0.707107 0" type="capsule" size="0.0150 0.0581" rgba="0.1 0.05333333333333334 0.6733333333333333 1" conaffinity="0" contype="0" solref="0.001 1" condim="1"/>
                                          <site name="S_17" pos="0 0 0" size="0.0135" rgba="0 0 0 0"/>
                                          <body name="B_18" pos="0.11612499999999999 0 0">
                                            <joint name="J_18" type="ball" pos="0 0 0" stiffness="0.0" damping="1.0" actuatorfrclimited="false"/>
                                            <geom name="G18" pos="0.058062499999999996 0 0" quat="0.707107 0 -0.707107 0" type="capsule" size="0.0150 0.0581" rgba="0.1 0.05333333333333334 0.6733333333333333 1" conaffinity="0" contype="0" solref="0.001 1" condim="1"/>
                                            <site name="S_18" pos="0 0 0" size="0.0135" rgba="0 0 0 0"/>
                                            <body name="B_19" pos="0.11612499999999999 0 0">
                                              <joint name="J_19" type="ball" pos="0 0 0" stiffness="0.0" damping="1.0" actuatorfrclimited="false"/>
                                              <geom name="G19" pos="0.058062499999999996 0 0" quat="0.707107 0 -0.707107 0" type="capsule" size="0.0150 0.0581" rgba="0.1 0.05333333333333334 0.6733333333333333 1" conaffinity="0" contype="0" solref="0.001 1" condim="1"/>
                                              <site name="S_19" pos="0 0 0" size="0.0135" rgba="0 0 0 0"/>
                                              <body name="B_20" pos="0.11612499999999999 0 0">
                                                <joint name="J_20" type="ball" pos="0 0 0" stiffness="0.0" damping="1.0" actuatorfrclimited="false"/>
                                                <geom name="G20" pos="0.058062499999999996 0 0" quat="0.707107 0 -0.707107 0" type="capsule" size="0.0150 0.0581" rgba="0.1 0.05333333333333334 0.6733333333333333 1" conaffinity="0" contype="0" solref="0.001 1" condim="1"/>
                                                <site name="S_20" pos="0 0 0" size="0.0135" rgba="0 0 0 0"/>
                                                <body name="B_21" pos="0.11612499999999999 0 0">
                                                  <joint name="J_21" type="ball" pos="0 0 0" stiffness="0.0" damping="1.0" actuatorfrclimited="false"/>
                                                  <geom name="G21" pos="0.058062499999999996 0 0" quat="0.707107 0 -0.707107 0" type="capsule" size="0.0150 0.0581" rgba="0.1 0.05333333333333334 0.6733333333333333 1" conaffinity="0" contype="0" solref="0.001 1" condim="1"/>
                                                  <site name="S_21" pos="0 0 0" size="0.0135" rgba="0 0 0 0"/>
                                                  <body name="B_22" pos="0.11612499999999999 0 0">
                                                    <joint name="J_22" type="ball" pos="0 0 0" stiffness="0.0" damping="1.0" actuatorfrclimited="false"/>
                                                    <geom name="G22" pos="0.058062499999999996 0 0" quat="0.707107 0 -0.707107 0" type="capsule" size="0.0150 0.0581" rgba="0.1 0.05333333333333334 0.6733333333333333 1" conaffinity="0" contype="0" solref="0.001 1" condim="1"/>
                                                    <site name="S_22" pos="0 0 0" size="0.0135" rgba="0 0 0 0"/>
                                                    <body name="B_23" pos="0.11612499999999999 0 0">
                                                      <joint name="J_23" type="ball" pos="0 0 0" stiffness="0.0" damping="1.0" actuatorfrclimited="false"/>
                                                      <geom name="G23" pos="0.058062499999999996 0 0" quat="0.707107 0 -0.707107 0" type="capsule" size="0.0150 0.0581" rgba="0.1 0.05333333333333334 0.6733333333333333 1" conaffinity="0" contype="0" solref="0.001 1" condim="1"/>
                                                      <site name="S_23" pos="0 0 0" size="0.0135" rgba="0 0 0 0"/>
                                                      <body name="B_24" pos="0.11612499999999999 0 0">
                                                        <joint name="J_24" type="ball" pos="0 0 0" stiffness="0.0" damping="1.0" actuatorfrclimited="false"/>
                                                        <geom name="G24" pos="0.058062499999999996 0 0" quat="0.707107 0 -0.707107 0" type="capsule" size="0.0150 0.0581" rgba="0.1 0.05333333333333334 0.6733333333333333 1" conaffinity="0" contype="0" solref="0.001 1" condim="1"/>
                                                        <site name="S_24" pos="0 0 0" size="0.0135" rgba="0 0 0 0"/>
                                                        <body name="B_25" pos="0.11612499999999999 0 0">
                                                          <joint name="J_25" type="ball" pos="0 0 0" stiffness="0.0" damping="1.0" actuatorfrclimited="false"/>
                                                          <geom name="G25" pos="0.058062499999999996 0 0" quat="0.707107 0 -0.707107 0" type="capsule" size="0.0150 0.0581" rgba="0.1 0.05333333333333334 0.6733333333333333 1" conaffinity="0" contype="0" solref="0.001 1" condim="1"/>
                                                          <site name="S_25" pos="0 0 0" size="0.0135" rgba="0 0 0 0"/>
                                                          <body name="B_26" pos="0.11612499999999999 0 0">
                                                            <joint name="J_26" type="ball" pos="0 0 0" stiffness="0.0" damping="1.0" actuatorfrclimited="false"/>
                                                            <geom name="G26" pos="0.058062499999999996 0 0" quat="0.707107 0 -0.707107 0" type="capsule" size="0.0150 0.0581" rgba="0.1 0.05333333333333334 0.6733333333333333 1" conaffinity="0" contype="0" solref="0.001 1" condim="1"/>
                                                            <site name="S_26" pos="0 0 0" size="0.0135" rgba="0 0 0 0"/>
                                                            <body name="B_27" pos="0.11612499999999999 0 0">
                                                              <joint name="J_27" type="ball" pos="0 0 0" stiffness="0.0" damping="1.0" actuatorfrclimited="false"/>
                                                              <geom name="G27" pos="0.058062499999999996 0 0" quat="0.707107 0 -0.707107 0" type="capsule" size="0.0150 0.0581" rgba="0.1 0.05333333333333334 0.6733333333333333 1" conaffinity="0" contype="0" solref="0.001 1" condim="1"/>
                                                              <site name="S_27" pos="0 0 0" size="0.0135" rgba="0 0 0 0"/>
                                                              <body name="B_28" pos="0.11612499999999999 0 0">
                                                                <joint name="J_28" type="ball" pos="0 0 0" stiffness="0.0" damping="1.0" actuatorfrclimited="false"/>
                                                                <geom name="G28" pos="0.058062499999999996 0 0" quat="0.707107 0 -0.707107 0" type="capsule" size="0.0150 0.0581" rgba="0.1 0.05333333333333334 0.6733333333333333 1" conaffinity="0" contype="0" solref="0.001 1" condim="1"/>
                                                                <site name="S_28" pos="0 0 0" size="0.0135" rgba="0 0 0 0"/>
                                                                <body name="B_29" pos="0.11612499999999999 0 0">
                                                                  <joint name="J_29" type="ball" pos="0 0 0" stiffness="0.0" damping="1.0" actuatorfrclimited="false"/>
                                                                  <geom name="G29" pos="0.058062499999999996 0 0" quat="0.707107 0 -0.707107 0" type="capsule" size="0.0150 0.0581" rgba="0.1 0.05333333333333334 0.6733333333333333 1" conaffinity="0" contype="0" solref="0.001 1" condim="1"/>
                                                                  <site name="S_29" pos="0 0 0" size="0.0135" rgba="0 0 0 0"/>
                                                                  <body name="B_30" pos="0.11612499999999999 0 0">
                                                                    <joint name="J_30" type="ball" pos="0 0 0" stiffness="0.0" damping="1.0" actuatorfrclimited="false"/>
                                                                    <geom name="G30" pos="0.058062499999999996 0 0" quat="0.707107 0 -0.707107 0" type="capsule" size="0.0150 0.0581" rgba="0.1 0.05333333333333334 0.6733333333333333 1" conaffinity="0" contype="0" solref="0.001 1" condim="1"/>
                                                                    <site name="S_30" pos="0 0 0" size="0.0135" rgba="0 0 0 0"/>
                                                                    <body name="B_31" pos="0.11612499999999999 0 0">
                                                                      <joint name="J_31" type="ball" pos="0 0 0" stiffness="0.0" damping="1.0" actuatorfrclimited="false"/>
                                                                      <geom name="G31" pos="0.058062499999999996 0 0" quat="0.707107 0 -0.707107 0" type="capsule" size="0.0150 0.0581" rgba="0.1 0.05333333333333334 0.6733333333333333 1" conaffinity="0" contype="0" solref="0.001 1" condim="1"/>
                                                                      <site name="S_31" pos="0 0 0" size="0.0135" rgba="0 0 0 0"/>
                                                                      <body name="B_32" pos="0.11612499999999999 0 0">
                                                                        <joint name="J_32" type="ball" pos="0 0 0" stiffness="0.0" damping="1.0" actuatorfrclimited="false"/>
                                                                        <geom name="G32" pos="0.058062499999999996 0 0" quat="0.707107 0 -0.707107 0" type="capsule" size="0.0150 0.0581" rgba="0.1 0.05333333333333334 0.6733333333333333 1" conaffinity="0" contype="0" solref="0.001 1" condim="1"/>
                                                                        <site name="S_32" pos="0 0 0" size="0.0135" rgba="0 0 0 0"/>
                                                                        <body name="B_33" pos="0.11612499999999999 0 0">
                                                                          <joint name="J_33" type="ball" pos="0 0 0" stiffness="0.0" damping="1.0" actuatorfrclimited="false"/>
                                                                          <geom name="G33" pos="0.058062499999999996 0 0" quat="0.707107 0 -0.707107 0" type="capsule" size="0.0150 0.0581" rgba="0.1 0.05333333333333334 0.6733333333333333 1" conaffinity="0" contype="0" solref="0.001 1" condim="1"/>
                                                                          <site name="S_33" pos="0 0 0" size="0.0135" rgba="0 0 0 0"/>
                                                                          <body name="B_34" pos="0.11612499999999999 0 0">
                                                                            <joint name="J_34" type="ball" pos="0 0 0" stiffness="0.0" damping="1.0" actuatorfrclimited="false"/>
                                                                            <geom name="G34" pos="0.058062499999999996 0 0" quat="0.707107 0 -0.707107 0" type="capsule" size="0.0150 0.0581" rgba="0.1 0.05333333333333334 0.6733333333333333 1" conaffinity="0" contype="0" solref="0.001 1" condim="1"/>
                                                                            <site name="S_34" pos="0 0 0" size="0.0135" rgba="0 0 0 0"/>
                                                                            <body name="B_35" pos="0.11612499999999999 0 0">
                                                                              <joint name="J_35" type="ball" pos="0 0 0" stiffness="0.0" damping="1.0" actuatorfrclimited="false"/>
                                                                              <geom name="G35" pos="0.058062499999999996 0 0" quat="0.707107 0 -0.707107 0" type="capsule" size="0.0150 0.0581" rgba="0.1 0.05333333333333334 0.6733333333333333 1" conaffinity="0" contype="0" solref="0.001 1" condim="1"/>
                                                                              <site name="S_35" pos="0 0 0" size="0.0135" rgba="0 0 0 0"/>
                                                                              <body name="B_36" pos="0.11612499999999999 0 0">
                                                                                <joint name="J_36" type="ball" pos="0 0 0" stiffness="0.0" damping="1.0" actuatorfrclimited="false"/>
                                                                                <geom name="G36" pos="0.058062499999999996 0 0" quat="0.707107 0 -0.707107 0" type="capsule" size="0.0150 0.0581" rgba="0.1 0.05333333333333334 0.6733333333333333 1" conaffinity="0" contype="0" solref="0.001 1" condim="1"/>
                                                                                <site name="S_36" pos="0 0 0" size="0.0135" rgba="0 0 0 0"/>
                                                                                <body name="B_37" pos="0.11612499999999999 0 0">
                                                                                  <joint name="J_37" type="ball" pos="0 0 0" stiffness="0.0" damping="1.0" actuatorfrclimited="false"/>
                                                                                  <geom name="G37" pos="0.058062499999999996 0 0" quat="0.707107 0 -0.707107 0" type="capsule" size="0.0150 0.0581" rgba="0.1 0.05333333333333334 0.6733333333333333 1" conaffinity="0" contype="0" solref="0.001 1" condim="1"/>
                                                                                  <site name="S_37" pos="0 0 0" size="0.0135" rgba="0 0 0 0"/>
                                                                                  <body name="B_38" pos="0.11612499999999999 0 0">
                                                                                    <joint name="J_38" type="ball" pos="0 0 0" stiffness="0.0" damping="1.0" actuatorfrclimited="false"/>
                                                                                    <geom name="G38" pos="0.058062499999999996 0 0" quat="0.707107 0 -0.707107 0" type="capsule" size="0.0150 0.0581" rgba="0.1 0.05333333333333334 0.6733333333333333 1" conaffinity="0" contype="0" solref="0.001 1" condim="1"/>
                                                                                    <site name="S_38" pos="0 0 0" size="0.0135" rgba="0 0 0 0"/>
                                                                                    <body name="B_39" pos="0.11612499999999999 0 0">
                                                                                      <joint name="J_39" type="ball" pos="0 0 0" stiffness="0.0" damping="1.0" actuatorfrclimited="false"/>
                                                                                      <geom name="G39" pos="0.058062499999999996 0 0" quat="0.707107 0 -0.707107 0" type="capsule" size="0.0150 0.0581" rgba="0.1 0.05333333333333334 0.6733333333333333 1" conaffinity="0" contype="0" solref="0.001 1" condim="1"/>
                                                                                      <site name="S_39" pos="0 0 0" size="0.0135" rgba="0 0 0 0"/>
                                                                                      <body name="B_40" pos="0.11612499999999999 0 0">
                                                                                        <joint name="J_40" type="ball" pos="0 0 0" stiffness="0.0" damping="1.0" actuatorfrclimited="false"/>
                                                                                        <geom name="G40" pos="0.058062499999999996 0 0" quat="0.707107 0 -0.707107 0" type="capsule" size="0.0150 0.0581" rgba="0.1 0.05333333333333334 0.6733333333333333 1" conaffinity="0" contype="0" solref="0.001 1" condim="1"/>
                                                                                        <site name="S_40" pos="0 0 0" size="0.0135" rgba="0 0 0 0"/>
                                                                                        <site name="twistcylx_41" pos="0 0 0.05" quat="0.707 0 0 -0.707" size="0.001 0.05" rgba="0 0 1 0.0" type="cylinder" group="1" />
                                                                                        <site name="twistcyly_41" pos="0 0.05 0" quat="0.707 -0.707 0 0" size="0.001 0.05" rgba="1 1 0 0.0" type="cylinder" group="1" />
                                                                                        <body name="B_41" pos="0.11612499999999999 0 0">
                                                                                          <joint name="J_41" type="ball" pos="0 0 0" stiffness="0.0" damping="1.0" actuatorfrclimited="false"/>
                                                                                          <geom name="G41" pos="0.058062499999999996 0 0" quat="0.707107 0 -0.707107 0" type="capsule" size="0.0150 0.0581" rgba="0.1 0.05333333333333334 0.6733333333333333 1" conaffinity="0" contype="0" solref="0.001 1" condim="1"/>
                                                                                          <site name="S_41" pos="0 0 0" size="0.0135" rgba="0 0 0 0"/>
                                                                                          <body name="B_42" pos="0.11612499999999999 0 0">
                                                                                            <joint name="J_42" type="ball" pos="0 0 0" stiffness="0.0" damping="1.0" actuatorfrclimited="false"/>
                                                                                            <geom name="G42" pos="0.058062499999999996 0 0" quat="0.707107 0 -0.707107 0" type="capsule" size="0.0150 0.0581" rgba="0.1 0.05333333333333334 0.6733333333333333 1" conaffinity="0" contype="0" solref="0.001 1" condim="1"/>
                                                                                            <site name="S_42" pos="0 0 0" size="0.0135" rgba="0 0 0 0"/>
                                                                                            <body name="B_43" pos="0.11612499999999999 0 0">
                                                                                              <joint name="J_43" type="ball" pos="0 0 0" stiffness="0.0" damping="1.0" actuatorfrclimited="false"/>
                                                                                              <geom name="G43" pos="0.058062499999999996 0 0" quat="0.707107 0 -0.707107 0" type="capsule" size="0.0150 0.0581" rgba="0.1 0.05333333333333334 0.6733333333333333 1" conaffinity="0" contype="0" solref="0.001 1" condim="1"/>
                                                                                              <site name="S_43" pos="0 0 0" size="0.0135" rgba="0 0 0 0"/>
                                                                                              <body name="B_44" pos="0.11612499999999999 0 0">
                                                                                                <joint name="J_44" type="ball" pos="0 0 0" stiffness="0.0" damping="1.0" actuatorfrclimited="false"/>
                                                                                                <geom name="G44" pos="0.058062499999999996 0 0" quat="0.707107 0 -0.707107 0" type="capsule" size="0.0150 0.0581" rgba="0.1 0.05333333333333334 0.6733333333333333 1" conaffinity="0" contype="0" solref="0.001 1" condim="1"/>
                                                                                                <site name="S_44" pos="0 0 0" size="0.0135" rgba="0 0 0 0"/>
                                                                                                <body name="B_45" pos="0.11612499999999999 0 0">
                                                                                                  <joint name="J_45" type="ball" pos="0 0 0" stiffness="0.0" damping="1.0" actuatorfrclimited="false"/>
                                                                                                  <geom name="G45" pos="0.058062499999999996 0 0" quat="0.707107 0 -0.707107 0" type="capsule" size="0.0150 0.0581" rgba="0.1 0.05333333333333334 0.6733333333333333 1" conaffinity="0" contype="0" solref="0.001 1" condim="1"/>
                                                                                                  <site name="S_45" pos="0 0 0" size="0.0135" rgba="0 0 0 0"/>
                                                                                                  <body name="B_46" pos="0.11612499999999999 0 0">
                                                                                                    <joint name="J_46" type="ball" pos="0 0 0" stiffness="0.0" damping="1.0" actuatorfrclimited="false"/>
                                                                                                    <geom name="G46" pos="0.058062499999999996 0 0" quat="0.707107 0 -0.707107 0" type="capsule" size="0.0150 0.0581" rgba="0.1 0.05333333333333334 0.6733333333333333 1" conaffinity="0" contype="0" solref="0.001 1" condim="1"/>
                                                                                                    <site name="S_46" pos="0 0 0" size="0.0135" rgba="0 0 0 0"/>
                                                                                                    <body name="B_47" pos="0.11612499999999999 0 0">
                                                                                                      <joint name="J_47" type="ball" pos="0 0 0" stiffness="0.0" damping="1.0" actuatorfrclimited="false"/>
                                                                                                      <geom name="G47" pos="0.058062499999999996 0 0" quat="0.707107 0 -0.707107 0" type="capsule" size="0.0150 0.0581" rgba="0.1 0.05333333333333334 0.6733333333333333 1" conaffinity="0" contype="0" solref="0.001 1" condim="1"/>
                                                                                                      <site name="S_47" pos="0 0 0" size="0.0135" rgba="0 0 0 0"/>
                                                                                                      <body name="B_48" pos="0.11612499999999999 0 0">
                                                                                                        <joint name="J_48" type="ball" pos="0 0 0" stiffness="0.0" damping="1.0" actuatorfrclimited="false"/>
                                                                                                        <geom name="G48" pos="0.058062499999999996 0 0" quat="0.707107 0 -0.707107 0" type="capsule" size="0.0150 0.0581" rgba="0.1 0.05333333333333334 0.6733333333333333 1" conaffinity="0" contype="0" solref="0.001 1" condim="1"/>
                                                                                                        <site name="S_48" pos="0 0 0" size="0.0135" rgba="0 0 0 0"/>
                                                                                                        <body name="B_49" pos="0.11612499999999999 0 0">
                                                                                                          <joint name="J_49" type="ball" pos="0 0 0" stiffness="0.0" damping="1.0" actuatorfrclimited="false"/>
                                                                                                          <geom name="G49" pos="0.058062499999999996 0 0" quat="0.707107 0 -0.707107 0" type="capsule" size="0.0150 0.0581" rgba="0.1 0.05333333333333334 0.6733333333333333 1" conaffinity="0" contype="0" solref="0.001 1" condim="1"/>
                                                                                                          <site name="S_49" pos="0 0 0" size="0.0135" rgba="0 0 0 0"/>
                                                                                                          <body name="B_50" pos="0.11612499999999999 0 0">
                                                                                                            <joint name="J_50" type="ball" pos="0 0 0" stiffness="0.0" damping="1.0" actuatorfrclimited="false"/>
                                                                                                            <geom name="G50" pos="0.058062499999999996 0 0" quat="0.707107 0 -0.707107 0" type="capsule" size="0.0150 0.0581" rgba="0.1 0.05333333333333334 0.6733333333333333 1" conaffinity="0" contype="0" solref="0.001 1" condim="1"/>
                                                                                                            <site name="S_50" pos="0 0 0" size="0.0135" rgba="0 0 0 0"/>
                                                                                                            <body name="B_51" pos="0.11612499999999999 0 0">
                                                                                                              <joint name="J_51" type="ball" pos="0 0 0" stiffness="0.0" damping="1.0" actuatorfrclimited="false"/>
                                                                                                              <geom name="G51" pos="0.058062499999999996 0 0" quat="0.707107 0 -0.707107 0" type="capsule" size="0.0150 0.0581" rgba="0.1 0.05333333333333334 0.6733333333333333 1" conaffinity="0" contype="0" solref="0.001 1" condim="1"/>
                                                                                                              <site name="S_51" pos="0 0 0" size="0.0135" rgba="0 0 0 0"/>
                                                                                                              <body name="B_52" pos="0.11612499999999999 0 0">
                                                                                                                <joint name="J_52" type="ball" pos="0 0 0" stiffness="0.0" damping="1.0" actuatorfrclimited="false"/>
                                                                                                                <geom name="G52" pos="0.058062499999999996 0 0" quat="0.707107 0 -0.707107 0" type="capsule" size="0.0150 0.0581" rgba="0.1 0.05333333333333334 0.6733333333333333 1" conaffinity="0" contype="0" solref="0.001 1" condim="1"/>
                                                                                                                <site name="S_52" pos="0 0 0" size="0.0135" rgba="0 0 0 0"/>
                                                                                                                <body name="B_53" pos="0.11612499999999999 0 0">
                                                                                                                  <joint name="J_53" type="ball" pos="0 0 0" stiffness="0.0" damping="1.0" actuatorfrclimited="false"/>
                                                                                                                  <geom name="G53" pos="0.058062499999999996 0 0" quat="0.707107 0 -0.707107 0" type="capsule" size="0.0150 0.0581" rgba="0.1 0.05333333333333334 0.6733333333333333 1" conaffinity="0" contype="0" solref="0.001 1" condim="1"/>
                                                                                                                  <site name="S_53" pos="0 0 0" size="0.0135" rgba="0 0 0 0"/>
                                                                                                                  <body name="B_54" pos="0.11612499999999999 0 0">
                                                                                                                    <joint name="J_54" type="ball" pos="0 0 0" stiffness="0.0" damping="1.0" actuatorfrclimited="false"/>
                                                                                                                    <geom name="G54" pos="0.058062499999999996 0 0" quat="0.707107 0 -0.707107 0" type="capsule" size="0.0150 0.0581" rgba="0.1 0.05333333333333334 0.6733333333333333 1" conaffinity="0" contype="0" solref="0.001 1" condim="1"/>
                                                                                                                    <site name="S_54" pos="0 0 0" size="0.0135" rgba="0 0 0 0"/>
                                                                                                                    <body name="B_55" pos="0.11612499999999999 0 0">
                                                                                                                      <joint name="J_55" type="ball" pos="0 0 0" stiffness="0.0" damping="1.0" actuatorfrclimited="false"/>
                                                                                                                      <geom name="G55" pos="0.058062499999999996 0 0" quat="0.707107 0 -0.707107 0" type="capsule" size="0.0150 0.0581" rgba="0.1 0.05333333333333334 0.6733333333333333 1" conaffinity="0" contype="0" solref="0.001 1" condim="1"/>
                                                                                                                      <site name="S_55" pos="0 0 0" size="0.0135" rgba="0 0 0 0"/>
                                                                                                                      <body name="B_56" pos="0.11612499999999999 0 0">
                                                                                                                        <joint name="J_56" type="ball" pos="0 0 0" stiffness="0.0" damping="1.0" actuatorfrclimited="false"/>
                                                                                                                        <geom name="G56" pos="0.058062499999999996 0 0" quat="0.707107 0 -0.707107 0" type="capsule" size="0.0150 0.0581" rgba="0.1 0.05333333333333334 0.6733333333333333 1" conaffinity="0" contype="0" solref="0.001 1" condim="1"/>
                                                                                                                        <site name="S_56" pos="0 0 0" size="0.0135" rgba="0 0 0 0"/>
                                                                                                                        <body name="B_57" pos="0.11612499999999999 0 0">
                                                                                                                          <joint name="J_57" type="ball" pos="0 0 0" stiffness="0.0" damping="1.0" actuatorfrclimited="false"/>
                                                                                                                          <geom name="G57" pos="0.058062499999999996 0 0" quat="0.707107 0 -0.707107 0" type="capsule" size="0.0150 0.0581" rgba="0.1 0.05333333333333334 0.6733333333333333 1" conaffinity="0" contype="0" solref="0.001 1" condim="1"/>
                                                                                                                          <site name="S_57" pos="0 0 0" size="0.0135" rgba="0 0 0 0"/>
                                                                                                                          <body name="B_58" pos="0.11612499999999999 0 0">
                                                                                                                            <joint name="J_58" type="ball" pos="0 0 0" stiffness="0.0" damping="1.0" actuatorfrclimited="false"/>
                                                                                                                            <geom name="G58" pos="0.058062499999999996 0 0" quat="0.707107 0 -0.707107 0" type="capsule" size="0.0150 0.0581" rgba="0.1 0.05333333333333334 0.6733333333333333 1" conaffinity="0" contype="0" solref="0.001 1" condim="1"/>
                                                                                                                            <site name="S_58" pos="0 0 0" size="0.0135" rgba="0 0 0 0"/>
                                                                                                                            <body name="B_59" pos="0.11612499999999999 0 0">
                                                                                                                              <joint name="J_59" type="ball" pos="0 0 0" stiffness="0.0" damping="1.0" actuatorfrclimited="false"/>
                                                                                                                              <geom name="G59" pos="0.058062499999999996 0 0" quat="0.707107 0 -0.707107 0" type="capsule" size="0.0150 0.0581" rgba="0.1 0.05333333333333334 0.6733333333333333 1" conaffinity="0" contype="0" solref="0.001 1" condim="1"/>
                                                                                                                              <site name="S_59" pos="0 0 0" size="0.0135" rgba="0 0 0 0"/>
                                                                                                                              <body name="B_60" pos="0.11612499999999999 0 0">
                                                                                                                                <joint name="J_60" type="ball" pos="0 0 0" stiffness="0.0" damping="1.0" actuatorfrclimited="false"/>
                                                                                                                                <geom name="G60" pos="0.058062499999999996 0 0" quat="0.707107 0 -0.707107 0" type="capsule" size="0.0150 0.0581" rgba="0.1 0.05333333333333334 0.6733333333333333 1" conaffinity="0" contype="0" solref="0.001 1" condim="1"/>
                                                                                                                                <site name="S_60" pos="0 0 0" size="0.0135" rgba="0 0 0 0"/>
                                                                                                                                <body name="B_61" pos="0.11612499999999999 0 0">
                                                                                                                                  <joint name="J_61" type="ball" pos="0 0 0" stiffness="0.0" damping="1.0" actuatorfrclimited="false"/>
                                                                                                                                  <geom name="G61" pos="0.058062499999999996 0 0" quat="0.707107 0 -0.707107 0" type="capsule" size="0.0150 0.0581" rgba="0.1 0.05333333333333334 0.6733333333333333 1" conaffinity="0" contype="0" solref="0.001 1" condim="1"/>
                                                                                                                                  <site name="S_61" pos="0 0 0" size="0.0135" rgba="0 0 0 0"/>
                                                                                                                                  <body name="B_62" pos="0.11612499999999999 0 0">
                                                                                                                                    <joint name="J_62" type="ball" pos="0 0 0" stiffness="0.0" damping="1.0" actuatorfrclimited="false"/>
                                                                                                                                    <geom name="G62" pos="0.058062499999999996 0 0" quat="0.707107 0 -0.707107 0" type="capsule" size="0.0150 0.0581" rgba="0.1 0.05333333333333334 0.6733333333333333 1" conaffinity="0" contype="0" solref="0.001 1" condim="1"/>
                                                                                                                                    <site name="S_62" pos="0 0 0" size="0.0135" rgba="0 0 0 0"/>
                                                                                                                                    <body name="B_63" pos="0.11612499999999999 0 0">
                                                                                                                                      <joint name="J_63" type="ball" pos="0 0 0" stiffness="0.0" damping="1.0" actuatorfrclimited="false"/>
                                                                                                                                      <geom name="G63" pos="0.058062499999999996 0 0" quat="0.707107 0 -0.707107 0" type="capsule" size="0.0150 0.0581" rgba="0.1 0.05333333333333334 0.6733333333333333 1" conaffinity="0" contype="0" solref="0.001 1" condim="1"/>
                                                                                                                                      <site name="S_63" pos="0 0 0" size="0.0135" rgba="0 0 0 0"/>
                                                                                                                                      <body name="B_64" pos="0.11612499999999999 0 0">
                                                                                                                                        <joint name="J_64" type="ball" pos="0 0 0" stiffness="0.0" damping="1.0" actuatorfrclimited="false"/>
                                                                                                                                        <geom name="G64" pos="0.058062499999999996 0 0" quat="0.707107 0 -0.707107 0" type="capsule" size="0.0150 0.0581" rgba="0.1 0.05333333333333334 0.6733333333333333 1" conaffinity="0" contype="0" solref="0.001 1" condim="1"/>
                                                                                                                                        <site name="S_64" pos="0 0 0" size="0.0135" rgba="0 0 0 0"/>
                                                                                                                                        <body name="B_65" pos="0.11612499999999999 0 0">
                                                                                                                                          <joint name="J_65" type="ball" pos="0 0 0" stiffness="0.0" damping="1.0" actuatorfrclimited="false"/>
                                                                                                                                          <geom name="G65" pos="0.058062499999999996 0 0" quat="0.707107 0 -0.707107 0" type="capsule" size="0.0150 0.0581" rgba="0.1 0.05333333333333334 0.6733333333333333 1" conaffinity="0" contype="0" solref="0.001 1" condim="1"/>
                                                                                                                                          <site name="S_65" pos="0 0 0" size="0.0135" rgba="0 0 0 0"/>
                                                                                                                                          <body name="B_66" pos="0.11612499999999999 0 0">
                                                                                                                                            <joint name="J_66" type="ball" pos="0 0 0" stiffness="0.0" damping="1.0" actuatorfrclimited="false"/>
                                                                                                                                            <geom name="G66" pos="0.058062499999999996 0 0" quat="0.707107 0 -0.707107 0" type="capsule" size="0.0150 0.0581" rgba="0.1 0.05333333333333334 0.6733333333333333 1" conaffinity="0" contype="0" solref="0.001 1" condim="1"/>
                                                                                                                                            <site name="S_66" pos="0 0 0" size="0.0135" rgba="0 0 0 0"/>
                                                                                                                                            <body name="B_67" pos="0.11612499999999999 0 0">
                                                                                                                                              <joint name="J_67" type="ball" pos="0 0 0" stiffness="0.0" damping="1.0" actuatorfrclimited="false"/>
                                                                                                                                              <geom name="G67" pos="0.058062499999999996 0 0" quat="0.707107 0 -0.707107 0" type="capsule" size="0.0150 0.0581" rgba="0.1 0.05333333333333334 0.6733333333333333 1" conaffinity="0" contype="0" solref="0.001 1" condim="1"/>
                                                                                                                                              <site name="S_67" pos="0 0 0" size="0.0135" rgba="0 0 0 0"/>
                                                                                                                                              <body name="B_68" pos="0.11612499999999999 0 0">
                                                                                                                                                <joint name="J_68" type="ball" pos="0 0 0" stiffness="0.0" damping="1.0" actuatorfrclimited="false"/>
                                                                                                                                                <geom name="G68" pos="0.058062499999999996 0 0" quat="0.707107 0 -0.707107 0" type="capsule" size="0.0150 0.0581" rgba="0.1 0.05333333333333334 0.6733333333333333 1" conaffinity="0" contype="0" solref="0.001 1" condim="1"/>
                                                                                                                                                <site name="S_68" pos="0 0 0" size="0.0135" rgba="0 0 0 0"/>
                                                                                                                                                <body name="B_69" pos="0.11612499999999999 0 0">
                                                                                                                                                  <joint name="J_69" type="ball" pos="0 0 0" stiffness="0.0" damping="1.0" actuatorfrclimited="false"/>
                                                                                                                                                  <geom name="G69" pos="0.058062499999999996 0 0" quat="0.707107 0 -0.707107 0" type="capsule" size="0.0150 0.0581" rgba="0.1 0.05333333333333334 0.6733333333333333 1" conaffinity="0" contype="0" solref="0.001 1" condim="1"/>
                                                                                                                                                  <site name="S_69" pos="0 0 0" size="0.0135" rgba="0 0 0 0"/>
                                                                                                                                                  <body name="B_70" pos="0.11612499999999999 0 0">
                                                                                                                                                    <joint name="J_70" type="ball" pos="0 0 0" stiffness="0.0" damping="1.0" actuatorfrclimited="false"/>
                                                                                                                                                    <geom name="G70" pos="0.058062499999999996 0 0" quat="0.707107 0 -0.707107 0" type="capsule" size="0.0150 0.0581" rgba="0.1 0.05333333333333334 0.6733333333333333 1" conaffinity="0" contype="0" solref="0.001 1" condim="1"/>
                                                                                                                                                    <site name="S_70" pos="0 0 0" size="0.0135" rgba="0 0 0 0"/>
                                                                                                                                                    <body name="B_71" pos="0.11612499999999999 0 0">
                                                                                                                                                      <joint name="J_71" type="ball" pos="0 0 0" stiffness="0.0" damping="1.0" actuatorfrclimited="false"/>
                                                                                                                                                      <geom name="G71" pos="0.058062499999999996 0 0" quat="0.707107 0 -0.707107 0" type="capsule" size="0.0150 0.0581" rgba="0.1 0.05333333333333334 0.6733333333333333 1" conaffinity="0" contype="0" solref="0.001 1" condim="1"/>
                                                                                                                                                      <site name="S_71" pos="0 0 0" size="0.0135" rgba="0 0 0 0"/>
                                                                                                                                                      <body name="B_72" pos="0.11612499999999999 0 0">
                                                                                                                                                        <joint name="J_72" type="ball" pos="0 0 0" stiffness="0.0" damping="1.0" actuatorfrclimited="false"/>
                                                                                                                                                        <geom name="G72" pos="0.058062499999999996 0 0" quat="0.707107 0 -0.707107 0" type="capsule" size="0.0150 0.0581" rgba="0.1 0.05333333333333334 0.6733333333333333 1" conaffinity="0" contype="0" solref="0.001 1" condim="1"/>
                                                                                                                                                        <site name="S_72" pos="0 0 0" size="0.0135" rgba="0 0 0 0"/>
                                                                                                                                                        <body name="B_73" pos="0.11612499999999999 0 0">
                                                                                                                                                          <joint name="J_73" type="ball" pos="0 0 0" stiffness="0.0" damping="1.0" actuatorfrclimited="false"/>
                                                                                                                                                          <geom name="G73" pos="0.058062499999999996 0 0" quat="0.707107 0 -0.707107 0" type="capsule" size="0.0150 0.0581" rgba="0.1 0.05333333333333334 0.6733333333333333 1" conaffinity="0" contype="0" solref="0.001 1" condim="1"/>
                                                                                                                                                          <site name="S_73" pos="0 0 0" size="0.0135" rgba="0 0 0 0"/>
                                                                                                                                                          <body name="B_74" pos="0.11612499999999999 0 0">
                                                                                                                                                            <joint name="J_74" type="ball" pos="0 0 0" stiffness="0.0" damping="1.0" actuatorfrclimited="false"/>
                                                                                                                                                            <geom name="G74" pos="0.058062499999999996 0 0" quat="0.707107 0 -0.707107 0" type="capsule" size="0.0150 0.0581" rgba="0.1 0.05333333333333334 0.6733333333333333 1" conaffinity="0" contype="0" solref="0.001 1" condim="1"/>
                                                                                                                                                            <site name="S_74" pos="0 0 0" size="0.0135" rgba="0 0 0 0"/>
                                                                                                                                                            <body name="B_75" pos="0.11612499999999999 0 0">
                                                                                                                                                              <joint name="J_75" type="ball" pos="0 0 0" stiffness="0.0" damping="1.0" actuatorfrclimited="false"/>
                                                                                                                                                              <geom name="G75" pos="0.058062499999999996 0 0" quat="0.707107 0 -0.707107 0" type="capsule" size="0.0150 0.0581" rgba="0.1 0.05333333333333334 0.6733333333333333 1" conaffinity="0" contype="0" solref="0.001 1" condim="1"/>
                                                                                                                                                              <site name="S_75" pos="0 0 0" size="0.0135" rgba="0 0 0 0"/>
                                                                                                                                                              <body name="B_76" pos="0.11612499999999999 0 0">
                                                                                                                                                                <joint name="J_76" type="ball" pos="0 0 0" stiffness="0.0" damping="1.0" actuatorfrclimited="false"/>
                                                                                                                                                                <geom name="G76" pos="0.058062499999999996 0 0" quat="0.707107 0 -0.707107 0" type="capsule" size="0.0150 0.0581" rgba="0.1 0.05333333333333334 0.6733333333333333 1" conaffinity="0" contype="0" solref="0.001 1" condim="1"/>
                                                                                                                                                                <site name="S_76" pos="0 0 0" size="0.0135" rgba="0 0 0 0"/>
                                                                                                                                                                <body name="B_77" pos="0.11612499999999999 0 0">
                                                                                                                                                                  <joint name="J_77" type="ball" pos="0 0 0" stiffness="0.0" damping="1.0" actuatorfrclimited="false"/>
                                                                                                                                                                  <geom name="G77" pos="0.058062499999999996 0 0" quat="0.707107 0 -0.707107 0" type="capsule" size="0.0150 0.0581" rgba="0.1 0.05333333333333334 0.6733333333333333 1" conaffinity="0" contype="0" solref="0.001 1" condim="1"/>
                                                                                                                                                                  <site name="S_77" pos="0 0 0" size="0.0135" rgba="0 0 0 0"/>
                                                                                                                                                                  <body name="B_78" pos="0.11612499999999999 0 0">
                                                                                                                                                                    <joint name="J_78" type="ball" pos="0 0 0" stiffness="0.0" damping="1.0" actuatorfrclimited="false"/>
                                                                                                                                                                    <geom name="G78" pos="0.058062499999999996 0 0" quat="0.707107 0 -0.707107 0" type="capsule" size="0.0150 0.0581" rgba="0.1 0.05333333333333334 0.6733333333333333 1" conaffinity="0" contype="0" solref="0.001 1" condim="1"/>
                                                                                                                                                                    <site name="S_78" pos="0 0 0" size="0.0135" rgba="0 0 0 0"/>
                                                                                                                                                                    <body name="B_last" pos="0.11612499999999999 0 0">
                                                                                                                                                                      <joint name="J_last" type="ball" pos="0 0 0" stiffness="0.0" damping="1.0" actuatorfrclimited="false"/>
                                                                                                                                                                      <geom name="G79" pos="0.058062499999999996 0 0" quat="0.707107 0 -0.707107 0" type="capsule" size="0.0150 0.0581" rgba="0.1 0.05333333333333334 0.6733333333333333 1" conaffinity="0" contype="0" solref="0.001 1" condim="1"/>
                                                                                                                                                                      <site name="S_79" pos="0 0 0" size="0.0135" rgba="0 0 0 0"/>
                                                                                                                                                                      <site name="twistcylx_80" pos="0 0 0.05" quat="0.707 0 0 -0.707" size="0.001 0.05" rgba="0 0 1 0.0" type="cylinder" group="1" />
                                                                                                                                                                      <site name="twistcyly_80" pos="0 0.05 0" quat="0.707 -0.707 0 0" size="0.001 0.05" rgba="1 1 0 0.0" type="cylinder" group="1" />
                                                                                                                                                                      <site name="S_last" pos="0.11612499999999999 0 0" size="0.0135"/>
                                                                                                                                                                      <body name="B_last2" pos="0.11612499999999999 0 0">
                                                                                                                                                                      </body>
                                                                                                                                                                    </body>
                                                                                                                                                                  </body>
                                                                                                                                                                </body>
                                                                                                                                                              </body>
                                                                                                                                                            </body>
                                                                                                                                                          </body>
                                                                                                                                                        </body>
                                                                                                                                                      </body>
                                                                                                                                                    </body>
                                                                                                                                                  </body>
                                                                                                                                                </body>
                                                                                                                                              </body>
                                                                                                                                            </body>
                                                                                                                                          </body>
                                                                                                                                        </body>
                                                                                                                                      </body>
                                                                                                                                    </body>
                                                                                                                                  </body>
                                                                                                                                </body>
                                                                                                                              </body>
                                                                                                                            </body>
                                                                                                                          </body>
                                                                                                                        </body>
                                                                                                                      </body>
                                                                                                                    </body>
                                                                                                                  </body>
                                                                                                                </body>
                                                                                                              </body>
                                                                                                            </body>
                                                                                                          </body>
                                                                                                        </body>
                                                                                                      </body>
                                                                                                    </body>
                                                                                                  </body>
                                                                                                </body>
                                                                                              </body>
                                                                                            </body>
                                                                                          </body>
                                                                                        </body>
                                                                                      </body>
                                                                                    </body>
                                                                                  </body>
                                                                                </body>
                                                                              </body>
                                                                            </body>
                                                                          </body>
                                                                        </body>
                                                                      </body>
                                                                    </body>
                                                                  </body>
                                                                </body>
                                                              </body>
                                                            </body>
                                                          </body>
                                                        </body>
                                                      </body>
                                                    </body>
                                                  </body>
                                                </body>
                                              </body>
                                            </body>
                                          </body>
                                        </body>
                                      </body>
                                    </body>
                                  </body>
                                </body>
                              </body>
                            </body>
                          </body>
                        </body>
                      </body>
                    </body>
                  </body>
                </body>
              </body>
            </body>
          </body>
        </body>
      </body>
    </body>
  </worldbody>
  <sensor>
  </sensor>
  <equality>
    <weld body1='B_last' body2='eef_body' solref='0.001 1'/>
     <weld body1='B_first' body2='eef_body2' solref='0.001 1'/>
  </equality>
  <contact>
    <exclude body1="B_first" body2="B_last"/>
    <exclude body1="B_1" body2="B_last"/>
    <exclude body1="B_first" body2="B_78"/>
    <exclude body1="B_first" body2="B_1"/>
    <exclude body1="B_1" body2="B_2"/>
    <exclude body1="B_2" body2="B_3"/>
    <exclude body1="B_3" body2="B_4"/>
    <exclude body1="B_4" body2="B_5"/>
    <exclude body1="B_5" body2="B_6"/>
    <exclude body1="B_6" body2="B_7"/>
    <exclude body1="B_7" body2="B_8"/>
    <exclude body1="B_8" body2="B_9"/>
    <exclude body1="B_9" body2="B_10"/>
    <exclude body1="B_10" body2="B_11"/>
    <exclude body1="B_11" body2="B_12"/>
    <exclude body1="B_12" body2="B_13"/>
    <exclude body1="B_13" body2="B_14"/>
    <exclude body1="B_14" body2="B_15"/>
    <exclude body1="B_15" body2="B_16"/>
    <exclude body1="B_16" body2="B_17"/>
    <exclude body1="B_17" body2="B_18"/>
    <exclude body1="B_18" body2="B_19"/>
    <exclude body1="B_19" body2="B_20"/>
    <exclude body1="B_20" body2="B_21"/>
    <exclude body1="B_21" body2="B_22"/>
    <exclude body1="B_22" body2="B_23"/>
    <exclude body1="B_23" body2="B_24"/>
    <exclude body1="B_24" body2="B_25"/>
    <exclude body1="B_25" body2="B_26"/>
    <exclude body1="B_26" body2="B_27"/>
    <exclude body1="B_27" body2="B_28"/>
    <exclude body1="B_28" body2="B_29"/>
    <exclude body1="B_29" body2="B_30"/>
    <exclude body1="B_30" body2="B_31"/>
    <exclude body1="B_31" body2="B_32"/>
    <exclude body1="B_32" body2="B_33"/>
    <exclude body1="B_33" body2="B_34"/>
    <exclude body1="B_34" body2="B_35"/>
    <exclude body1="B_35" body2="B_36"/>
    <exclude body1="B_36" body2="B_37"/>
    <exclude body1="B_37" body2="B_38"/>
    <exclude body1="B_38" body2="B_39"/>
    <exclude body1="B_39" body2="B_40"/>
    <exclude body1="B_40" body2="B_41"/>
    <exclude body1="B_41" body2="B_42"/>
    <exclude body1="B_42" body2="B_43"/>
    <exclude body1="B_43" body2="B_44"/>
    <exclude body1="B_44" body2="B_45"/>
    <exclude body1="B_45" body2="B_46"/>
    <exclude body1="B_46" body2="B_47"/>
    <exclude body1="B_47" body2="B_48"/>
    <exclude body1="B_48" body2="B_49"/>
    <exclude body1="B_49" body2="B_50"/>
    <exclude body1="B_50" body2="B_51"/>
    <exclude body1="B_51" body2="B_52"/>
    <exclude body1="B_52" body2="B_53"/>
    <exclude body1="B_53" body2="B_54"/>
    <exclude body1="B_54" body2="B_55"/>
    <exclude body1="B_55" body2="B_56"/>
    <exclude body1="B_56" body2="B_57"/>
    <exclude body1="B_57" body2="B_58"/>
    <exclude body1="B_58" body2="B_59"/>
    <exclude body1="B_59" body2="B_60"/>
    <exclude body1="B_60" body2="B_61"/>
    <exclude body1="B_61" body2="B_62"/>
    <exclude body1="B_62" body2="B_63"/>
    <exclude body1="B_63" body2="B_64"/>
    <exclude body1="B_64" body2="B_65"/>
    <exclude body1="B_65" body2="B_66"/>
    <exclude body1="B_66" body2="B_67"/>
    <exclude body1="B_67" body2="B_68"/>
    <exclude body1="B_68" body2="B_69"/>
    <exclude body1="B_69" body2="B_70"/>
    <exclude body1="B_70" body2="B_71"/>
    <exclude body1="B_71" body2="B_72"/>
    <exclude body1="B_72" body2="B_73"/>
    <exclude body1="B_73" body2="B_74"/>
    <exclude body1="B_74" body2="B_75"/>
    <exclude body1="B_75" body2="B_76"/>
    <exclude body1="B_76" body2="B_77"/>
    <exclude body1="B_77" body2="B_78"/>
    <exclude body1="B_78" body2="B_last"/>
    <exclude body1="eef_body" body2="B_first"/>
    <exclude body1="eef_body" body2="B_last"/>
    <exclude body1="eef_body" body2="B_78"/>
  </contact>
</mujoco>
