<mujoco model="base">
  <compiler angle="radian"/>
  <option timestep="0.0015" tolerance="1e-10" integrator="implicit" cone="elliptic" jacobian="sparse" iterations="30"/>
  <size njmax="5000" nconmax="5000"/>
  <visual>
    <quality shadowsize="2048"/>
    <map stiffness="700" fogstart="10" fogend="15" znear="0.001" zfar="40" shadowscale="0.5"/>
    <rgba haze="0.15 0.25 0.35 1"/>
  </visual>
  <statistic meansize="0.05" extent="2"/>
  <asset>
    <texture type="skybox" builtin="gradient" rgb1="1 1 0.9" rgb2="0.9 0.9 0.81" width="512" height="3072"/>
    <texture type="2d" name="texplane" builtin="checker" mark="cross" rgb1="0.2 0.3 0.4" rgb2="0.1 0.15 0.2" markrgb="0.8 0.8 0.8" width="512" height="512"/>
    <material name="matplane" texture="texplane" texuniform="true" reflectance="0.3"/>
  </asset>
  <worldbody>
    <geom name="floor" size="3 3 0.125" pos="0 0 -10" type="plane" condim="1" material="matplane"/>
    <camera pos="0 -1 1.5" quat="0.866019 0.500011 0 0"/>
    <camera pos="1 -1.2 0.8" quat="0.687095 0.527073 0.304042 0.397055"/>
    <camera pos="-1.8 -1.1 0.7" quat="0.732963 0.562422 -0.232963 -0.303603"/>
    <camera pos="-1 -1.5 0.5" quat="0.707107 0.707107 0 0"/>
    <camera pos="9.7 -1 1.1" quat="0.687095 0.527073 0.304042 0.397055"/>
    <camera pos="4.5 -8 0.5" quat="0.707107 0.707107 0 0"/>
    <light pos="0 0 5" dir="0 0 -1" directional="true" castshadow="false" diffuse="0.4 0.4 0.4" specular="0.1 0.1 0.1"/>
    <light pos="0 0 4" dir="0 0 -1" directional="true" diffuse="0.6 0.6 0.6" specular="0.2 0.2 0.2"/>
    <body name="eef_body" pos="-4.645 0 0.5">
      <geom name="eef_geom" size="0.05 0.05 0.1" type="box" contype="0" conaffinity="0" mass="1" rgba="0.8 0.2 0.1 0"/>
    </body>
    <body name="eef_body2" pos="4.645 0 0.5">
      <geom name="eef_geom2" size="0.05 0.05 0.1" type="box" contype="0" conaffinity="0" mass="1" rgba="0.8 0.2 0.1 0"/>
    </body>
    <body name="stiffrope" pos="4.645 0 0.5" quat="0 0 1 0">
      <joint name="freejoint_A" type="free" limited="false" actuatorfrclimited="false"/>
      <site name="ft_rope" pos="0 0 0" size="0.05" group="1" rgba="1 0 0 0"/>
      <body name="B_first">
        <geom name="G0" size="0.025 0.1161" pos="0.116125 0 0" quat="0.707107 0 -0.707107 0" type="capsule" contype="0" conaffinity="0" condim="1" rgba="0.1 0.0533333 0.673333 1"/>
        <site name="S_first" pos="0 0 0"/>
        <site name="S_0" pos="0 0 0"/>
        <site name="twistcylx_1" pos="0 0 0.05" quat="0.707107 0 0 -0.707107" size="0.001 0.05" group="1" type="cylinder" rgba="0 0 1 0"/>
        <site name="twistcyly_1" pos="0 0.05 0" quat="0.707107 -0.707107 0 0" size="0.001 0.05" group="1" type="cylinder" rgba="1 1 0 0"/>
        <body name="B_1" pos="0.23225 0 0">
          <joint name="J_1" pos="0 0 0" type="ball" actuatorfrclimited="false" damping="0.5"/>
          <geom name="G1" size="0.025 0.1161" pos="0.116125 0 0" quat="0.707107 0 -0.707107 0" type="capsule" contype="0" conaffinity="0" condim="1" rgba="0.1 0.0533333 0.673333 1"/>
          <site name="S_1" pos="0 0 0"/>
          <body name="B_2" pos="0.23225 0 0">
            <joint name="J_2" pos="0 0 0" type="ball" actuatorfrclimited="false" damping="0.5"/>
            <geom name="G2" size="0.025 0.1161" pos="0.116125 0 0" quat="0.707107 0 -0.707107 0" type="capsule" contype="0" conaffinity="0" condim="1" rgba="0.1 0.0533333 0.673333 1"/>
            <site name="S_2" pos="0 0 0"/>
            <body name="B_3" pos="0.23225 0 0">
              <joint name="J_3" pos="0 0 0" type="ball" actuatorfrclimited="false" damping="0.5"/>
              <geom name="G3" size="0.025 0.1161" pos="0.116125 0 0" quat="0.707107 0 -0.707107 0" type="capsule" contype="0" conaffinity="0" condim="1" rgba="0.1 0.0533333 0.673333 1"/>
              <site name="S_3" pos="0 0 0"/>
              <body name="B_4" pos="0.23225 0 0">
                <joint name="J_4" pos="0 0 0" type="ball" actuatorfrclimited="false" damping="0.5"/>
                <geom name="G4" size="0.025 0.1161" pos="0.116125 0 0" quat="0.707107 0 -0.707107 0" type="capsule" contype="0" conaffinity="0" condim="1" rgba="0.1 0.0533333 0.673333 1"/>
                <site name="S_4" pos="0 0 0"/>
                <body name="B_5" pos="0.23225 0 0">
                  <joint name="J_5" pos="0 0 0" type="ball" actuatorfrclimited="false" damping="0.5"/>
                  <geom name="G5" size="0.025 0.1161" pos="0.116125 0 0" quat="0.707107 0 -0.707107 0" type="capsule" contype="0" conaffinity="0" condim="1" rgba="0.1 0.0533333 0.673333 1"/>
                  <site name="S_5" pos="0 0 0"/>
                  <body name="B_6" pos="0.23225 0 0">
                    <joint name="J_6" pos="0 0 0" type="ball" actuatorfrclimited="false" damping="0.5"/>
                    <geom name="G6" size="0.025 0.1161" pos="0.116125 0 0" quat="0.707107 0 -0.707107 0" type="capsule" contype="0" conaffinity="0" condim="1" rgba="0.1 0.0533333 0.673333 1"/>
                    <site name="S_6" pos="0 0 0"/>
                    <body name="B_7" pos="0.23225 0 0">
                      <joint name="J_7" pos="0 0 0" type="ball" actuatorfrclimited="false" damping="0.5"/>
                      <geom name="G7" size="0.025 0.1161" pos="0.116125 0 0" quat="0.707107 0 -0.707107 0" type="capsule" contype="0" conaffinity="0" condim="1" rgba="0.1 0.0533333 0.673333 1"/>
                      <site name="S_7" pos="0 0 0"/>
                      <body name="B_8" pos="0.23225 0 0">
                        <joint name="J_8" pos="0 0 0" type="ball" actuatorfrclimited="false" damping="0.5"/>
                        <geom name="G8" size="0.025 0.1161" pos="0.116125 0 0" quat="0.707107 0 -0.707107 0" type="capsule" contype="0" conaffinity="0" condim="1" rgba="0.1 0.0533333 0.673333 1"/>
                        <site name="S_8" pos="0 0 0"/>
                        <body name="B_9" pos="0.23225 0 0">
                          <joint name="J_9" pos="0 0 0" type="ball" actuatorfrclimited="false" damping="0.5"/>
                          <geom name="G9" size="0.025 0.1161" pos="0.116125 0 0" quat="0.707107 0 -0.707107 0" type="capsule" contype="0" conaffinity="0" condim="1" rgba="0.1 0.0533333 0.673333 1"/>
                          <site name="S_9" pos="0 0 0"/>
                          <body name="B_10" pos="0.23225 0 0">
                            <joint name="J_10" pos="0 0 0" type="ball" actuatorfrclimited="false" damping="0.5"/>
                            <geom name="G10" size="0.025 0.1161" pos="0.116125 0 0" quat="0.707107 0 -0.707107 0" type="capsule" contype="0" conaffinity="0" condim="1" rgba="0.1 0.0533333 0.673333 1"/>
                            <site name="S_10" pos="0 0 0"/>
                            <body name="B_11" pos="0.23225 0 0">
                              <joint name="J_11" pos="0 0 0" type="ball" actuatorfrclimited="false" damping="0.5"/>
                              <geom name="G11" size="0.025 0.1161" pos="0.116125 0 0" quat="0.707107 0 -0.707107 0" type="capsule" contype="0" conaffinity="0" condim="1" rgba="0.1 0.0533333 0.673333 1"/>
                              <site name="S_11" pos="0 0 0"/>
                              <body name="B_12" pos="0.23225 0 0">
                                <joint name="J_12" pos="0 0 0" type="ball" actuatorfrclimited="false" damping="0.5"/>
                                <geom name="G12" size="0.025 0.1161" pos="0.116125 0 0" quat="0.707107 0 -0.707107 0" type="capsule" contype="0" conaffinity="0" condim="1" rgba="0.1 0.0533333 0.673333 1"/>
                                <site name="S_12" pos="0 0 0"/>
                                <body name="B_13" pos="0.23225 0 0">
                                  <joint name="J_13" pos="0 0 0" type="ball" actuatorfrclimited="false" damping="0.5"/>
                                  <geom name="G13" size="0.025 0.1161" pos="0.116125 0 0" quat="0.707107 0 -0.707107 0" type="capsule" contype="0" conaffinity="0" condim="1" rgba="0.1 0.0533333 0.673333 1"/>
                                  <site name="S_13" pos="0 0 0"/>
                                  <body name="B_14" pos="0.23225 0 0">
                                    <joint name="J_14" pos="0 0 0" type="ball" actuatorfrclimited="false" damping="0.5"/>
                                    <geom name="G14" size="0.025 0.1161" pos="0.116125 0 0" quat="0.707107 0 -0.707107 0" type="capsule" contype="0" conaffinity="0" condim="1" rgba="0.1 0.0533333 0.673333 1"/>
                                    <site name="S_14" pos="0 0 0"/>
                                    <body name="B_15" pos="0.23225 0 0">
                                      <joint name="J_15" pos="0 0 0" type="ball" actuatorfrclimited="false" damping="0.5"/>
                                      <geom name="G15" size="0.025 0.1161" pos="0.116125 0 0" quat="0.707107 0 -0.707107 0" type="capsule" contype="0" conaffinity="0" condim="1" rgba="0.1 0.0533333 0.673333 1"/>
                                      <site name="S_15" pos="0 0 0"/>
                                      <body name="B_16" pos="0.23225 0 0">
                                        <joint name="J_16" pos="0 0 0" type="ball" actuatorfrclimited="false" damping="0.5"/>
                                        <geom name="G16" size="0.025 0.1161" pos="0.116125 0 0" quat="0.707107 0 -0.707107 0" type="capsule" contype="0" conaffinity="0" condim="1" rgba="0.1 0.0533333 0.673333 1"/>
                                        <site name="S_16" pos="0 0 0"/>
                                        <body name="B_17" pos="0.23225 0 0">
                                          <joint name="J_17" pos="0 0 0" type="ball" actuatorfrclimited="false" damping="0.5"/>
                                          <geom name="G17" size="0.025 0.1161" pos="0.116125 0 0" quat="0.707107 0 -0.707107 0" type="capsule" contype="0" conaffinity="0" condim="1" rgba="0.1 0.0533333 0.673333 1"/>
                                          <site name="S_17" pos="0 0 0"/>
                                          <body name="B_18" pos="0.23225 0 0">
                                            <joint name="J_18" pos="0 0 0" type="ball" actuatorfrclimited="false" damping="0.5"/>
                                            <geom name="G18" size="0.025 0.1161" pos="0.116125 0 0" quat="0.707107 0 -0.707107 0" type="capsule" contype="0" conaffinity="0" condim="1" rgba="0.1 0.0533333 0.673333 1"/>
                                            <site name="S_18" pos="0 0 0"/>
                                            <body name="B_19" pos="0.23225 0 0">
                                              <joint name="J_19" pos="0 0 0" type="ball" actuatorfrclimited="false" damping="0.5"/>
                                              <geom name="G19" size="0.025 0.1161" pos="0.116125 0 0" quat="0.707107 0 -0.707107 0" type="capsule" contype="0" conaffinity="0" condim="1" rgba="0.1 0.0533333 0.673333 1"/>
                                              <site name="S_19" pos="0 0 0"/>
                                              <body name="B_20" pos="0.23225 0 0">
                                                <joint name="J_20" pos="0 0 0" type="ball" actuatorfrclimited="false" damping="0.5"/>
                                                <geom name="G20" size="0.025 0.1161" pos="0.116125 0 0" quat="0.707107 0 -0.707107 0" type="capsule" contype="0" conaffinity="0" condim="1" rgba="0.1 0.0533333 0.673333 1"/>
                                                <site name="S_20" pos="0 0 0"/>
                                                <site name="twistcylx_21" pos="0 0 0.05" quat="0.707107 0 0 -0.707107" size="0.001 0.05" group="1" type="cylinder" rgba="0 0 1 0"/>
                                                <site name="twistcyly_21" pos="0 0.05 0" quat="0.707107 -0.707107 0 0" size="0.001 0.05" group="1" type="cylinder" rgba="1 1 0 0"/>
                                                <body name="B_21" pos="0.23225 0 0">
                                                  <joint name="J_21" pos="0 0 0" type="ball" actuatorfrclimited="false" damping="0.5"/>
                                                  <geom name="G21" size="0.025 0.1161" pos="0.116125 0 0" quat="0.707107 0 -0.707107 0" type="capsule" contype="0" conaffinity="0" condim="1" rgba="0.1 0.0533333 0.673333 1"/>
                                                  <site name="S_21" pos="0 0 0"/>
                                                  <body name="B_22" pos="0.23225 0 0">
                                                    <joint name="J_22" pos="0 0 0" type="ball" actuatorfrclimited="false" damping="0.5"/>
                                                    <geom name="G22" size="0.025 0.1161" pos="0.116125 0 0" quat="0.707107 0 -0.707107 0" type="capsule" contype="0" conaffinity="0" condim="1" rgba="0.1 0.0533333 0.673333 1"/>
                                                    <site name="S_22" pos="0 0 0"/>
                                                    <body name="B_23" pos="0.23225 0 0">
                                                      <joint name="J_23" pos="0 0 0" type="ball" actuatorfrclimited="false" damping="0.5"/>
                                                      <geom name="G23" size="0.025 0.1161" pos="0.116125 0 0" quat="0.707107 0 -0.707107 0" type="capsule" contype="0" conaffinity="0" condim="1" rgba="0.1 0.0533333 0.673333 1"/>
                                                      <site name="S_23" pos="0 0 0"/>
                                                      <body name="B_24" pos="0.23225 0 0">
                                                        <joint name="J_24" pos="0 0 0" type="ball" actuatorfrclimited="false" damping="0.5"/>
                                                        <geom name="G24" size="0.025 0.1161" pos="0.116125 0 0" quat="0.707107 0 -0.707107 0" type="capsule" contype="0" conaffinity="0" condim="1" rgba="0.1 0.0533333 0.673333 1"/>
                                                        <site name="S_24" pos="0 0 0"/>
                                                        <body name="B_25" pos="0.23225 0 0">
                                                          <joint name="J_25" pos="0 0 0" type="ball" actuatorfrclimited="false" damping="0.5"/>
                                                          <geom name="G25" size="0.025 0.1161" pos="0.116125 0 0" quat="0.707107 0 -0.707107 0" type="capsule" contype="0" conaffinity="0" condim="1" rgba="0.1 0.0533333 0.673333 1"/>
                                                          <site name="S_25" pos="0 0 0"/>
                                                          <body name="B_26" pos="0.23225 0 0">
                                                            <joint name="J_26" pos="0 0 0" type="ball" actuatorfrclimited="false" damping="0.5"/>
                                                            <geom name="G26" size="0.025 0.1161" pos="0.116125 0 0" quat="0.707107 0 -0.707107 0" type="capsule" contype="0" conaffinity="0" condim="1" rgba="0.1 0.0533333 0.673333 1"/>
                                                            <site name="S_26" pos="0 0 0"/>
                                                            <body name="B_27" pos="0.23225 0 0">
                                                              <joint name="J_27" pos="0 0 0" type="ball" actuatorfrclimited="false" damping="0.5"/>
                                                              <geom name="G27" size="0.025 0.1161" pos="0.116125 0 0" quat="0.707107 0 -0.707107 0" type="capsule" contype="0" conaffinity="0" condim="1" rgba="0.1 0.0533333 0.673333 1"/>
                                                              <site name="S_27" pos="0 0 0"/>
                                                              <body name="B_28" pos="0.23225 0 0">
                                                                <joint name="J_28" pos="0 0 0" type="ball" actuatorfrclimited="false" damping="0.5"/>
                                                                <geom name="G28" size="0.025 0.1161" pos="0.116125 0 0" quat="0.707107 0 -0.707107 0" type="capsule" contype="0" conaffinity="0" condim="1" rgba="0.1 0.0533333 0.673333 1"/>
                                                                <site name="S_28" pos="0 0 0"/>
                                                                <body name="B_29" pos="0.23225 0 0">
                                                                  <joint name="J_29" pos="0 0 0" type="ball" actuatorfrclimited="false" damping="0.5"/>
                                                                  <geom name="G29" size="0.025 0.1161" pos="0.116125 0 0" quat="0.707107 0 -0.707107 0" type="capsule" contype="0" conaffinity="0" condim="1" rgba="0.1 0.0533333 0.673333 1"/>
                                                                  <site name="S_29" pos="0 0 0"/>
                                                                  <body name="B_30" pos="0.23225 0 0">
                                                                    <joint name="J_30" pos="0 0 0" type="ball" actuatorfrclimited="false" damping="0.5"/>
                                                                    <geom name="G30" size="0.025 0.1161" pos="0.116125 0 0" quat="0.707107 0 -0.707107 0" type="capsule" contype="0" conaffinity="0" condim="1" rgba="0.1 0.0533333 0.673333 1"/>
                                                                    <site name="S_30" pos="0 0 0"/>
                                                                    <body name="B_31" pos="0.23225 0 0">
                                                                      <joint name="J_31" pos="0 0 0" type="ball" actuatorfrclimited="false" damping="0.5"/>
                                                                      <geom name="G31" size="0.025 0.1161" pos="0.116125 0 0" quat="0.707107 0 -0.707107 0" type="capsule" contype="0" conaffinity="0" condim="1" rgba="0.1 0.0533333 0.673333 1"/>
                                                                      <site name="S_31" pos="0 0 0"/>
                                                                      <body name="B_32" pos="0.23225 0 0">
                                                                        <joint name="J_32" pos="0 0 0" type="ball" actuatorfrclimited="false" damping="0.5"/>
                                                                        <geom name="G32" size="0.025 0.1161" pos="0.116125 0 0" quat="0.707107 0 -0.707107 0" type="capsule" contype="0" conaffinity="0" condim="1" rgba="0.1 0.0533333 0.673333 1"/>
                                                                        <site name="S_32" pos="0 0 0"/>
                                                                        <body name="B_33" pos="0.23225 0 0">
                                                                          <joint name="J_33" pos="0 0 0" type="ball" actuatorfrclimited="false" damping="0.5"/>
                                                                          <geom name="G33" size="0.025 0.1161" pos="0.116125 0 0" quat="0.707107 0 -0.707107 0" type="capsule" contype="0" conaffinity="0" condim="1" rgba="0.1 0.0533333 0.673333 1"/>
                                                                          <site name="S_33" pos="0 0 0"/>
                                                                          <body name="B_34" pos="0.23225 0 0">
                                                                            <joint name="J_34" pos="0 0 0" type="ball" actuatorfrclimited="false" damping="0.5"/>
                                                                            <geom name="G34" size="0.025 0.1161" pos="0.116125 0 0" quat="0.707107 0 -0.707107 0" type="capsule" contype="0" conaffinity="0" condim="1" rgba="0.1 0.0533333 0.673333 1"/>
                                                                            <site name="S_34" pos="0 0 0"/>
                                                                            <body name="B_35" pos="0.23225 0 0">
                                                                              <joint name="J_35" pos="0 0 0" type="ball" actuatorfrclimited="false" damping="0.5"/>
                                                                              <geom name="G35" size="0.025 0.1161" pos="0.116125 0 0" quat="0.707107 0 -0.707107 0" type="capsule" contype="0" conaffinity="0" condim="1" rgba="0.1 0.0533333 0.673333 1"/>
                                                                              <site name="S_35" pos="0 0 0"/>
                                                                              <body name="B_36" pos="0.23225 0 0">
                                                                                <joint name="J_36" pos="0 0 0" type="ball" actuatorfrclimited="false" damping="0.5"/>
                                                                                <geom name="G36" size="0.025 0.1161" pos="0.116125 0 0" quat="0.707107 0 -0.707107 0" type="capsule" contype="0" conaffinity="0" condim="1" rgba="0.1 0.0533333 0.673333 1"/>
                                                                                <site name="S_36" pos="0 0 0"/>
                                                                                <body name="B_37" pos="0.23225 0 0">
                                                                                  <joint name="J_37" pos="0 0 0" type="ball" actuatorfrclimited="false" damping="0.5"/>
                                                                                  <geom name="G37" size="0.025 0.1161" pos="0.116125 0 0" quat="0.707107 0 -0.707107 0" type="capsule" contype="0" conaffinity="0" condim="1" rgba="0.1 0.0533333 0.673333 1"/>
                                                                                  <site name="S_37" pos="0 0 0"/>
                                                                                  <body name="B_38" pos="0.23225 0 0">
                                                                                    <joint name="J_38" pos="0 0 0" type="ball" actuatorfrclimited="false" damping="0.5"/>
                                                                                    <geom name="G38" size="0.025 0.1161" pos="0.116125 0 0" quat="0.707107 0 -0.707107 0" type="capsule" contype="0" conaffinity="0" condim="1" rgba="0.1 0.0533333 0.673333 1"/>
                                                                                    <site name="S_38" pos="0 0 0"/>
                                                                                    <body name="B_last" pos="0.23225 0 0">
                                                                                      <joint name="J_last" pos="0 0 0" type="ball" actuatorfrclimited="false" damping="0.5"/>
                                                                                      <geom name="G39" size="0.025 0.1161" pos="0.116125 0 0" quat="0.707107 0 -0.707107 0" type="capsule" contype="0" conaffinity="0" condim="1" rgba="0.1 0.0533333 0.673333 1"/>
                                                                                      <site name="S_39" pos="0 0 0"/>
                                                                                      <site name="twistcylx_40" pos="0 0 0.05" quat="0.707107 0 0 -0.707107" size="0.001 0.05" group="1" type="cylinder" rgba="0 0 1 0"/>
                                                                                      <site name="twistcyly_40" pos="0 0.05 0" quat="0.707107 -0.707107 0 0" size="0.001 0.05" group="1" type="cylinder" rgba="1 1 0 0"/>
                                                                                      <site name="S_last" pos="0.23225 0 0"/>
                                                                                      <body name="B_last2" pos="0.23225 0 0"/>
                                                                                    </body>
                                                                                  </body>
                                                                                </body>
                                                                              </body>
                                                                            </body>
                                                                          </body>
                                                                        </body>
                                                                      </body>
                                                                    </body>
                                                                  </body>
                                                                </body>
                                                              </body>
                                                            </body>
                                                          </body>
                                                        </body>
                                                      </body>
                                                    </body>
                                                  </body>
                                                </body>
                                              </body>
                                            </body>
                                          </body>
                                        </body>
                                      </body>
                                    </body>
                                  </body>
                                </body>
                              </body>
                            </body>
                          </body>
                        </body>
                      </body>
                    </body>
                  </body>
                </body>
              </body>
            </body>
          </body>
        </body>
      </body>
    </body>
  </worldbody>
  <contact>
    <exclude body1="eef_body" body2="B_first"/>
    <exclude body1="eef_body" body2="B_38"/>
    <exclude body1="eef_body" body2="B_last"/>
    <exclude body1="B_first" body2="B_1"/>
    <exclude body1="B_first" body2="B_38"/>
    <exclude body1="B_first" body2="B_last"/>
    <exclude body1="B_1" body2="B_2"/>
    <exclude body1="B_1" body2="B_last"/>
    <exclude body1="B_2" body2="B_3"/>
    <exclude body1="B_3" body2="B_4"/>
    <exclude body1="B_4" body2="B_5"/>
    <exclude body1="B_5" body2="B_6"/>
    <exclude body1="B_6" body2="B_7"/>
    <exclude body1="B_7" body2="B_8"/>
    <exclude body1="B_8" body2="B_9"/>
    <exclude body1="B_9" body2="B_10"/>
    <exclude body1="B_10" body2="B_11"/>
    <exclude body1="B_11" body2="B_12"/>
    <exclude body1="B_12" body2="B_13"/>
    <exclude body1="B_13" body2="B_14"/>
    <exclude body1="B_14" body2="B_15"/>
    <exclude body1="B_15" body2="B_16"/>
    <exclude body1="B_16" body2="B_17"/>
    <exclude body1="B_17" body2="B_18"/>
    <exclude body1="B_18" body2="B_19"/>
    <exclude body1="B_19" body2="B_20"/>
    <exclude body1="B_20" body2="B_21"/>
    <exclude body1="B_21" body2="B_22"/>
    <exclude body1="B_22" body2="B_23"/>
    <exclude body1="B_23" body2="B_24"/>
    <exclude body1="B_24" body2="B_25"/>
    <exclude body1="B_25" body2="B_26"/>
    <exclude body1="B_26" body2="B_27"/>
    <exclude body1="B_27" body2="B_28"/>
    <exclude body1="B_28" body2="B_29"/>
    <exclude body1="B_29" body2="B_30"/>
    <exclude body1="B_30" body2="B_31"/>
    <exclude body1="B_31" body2="B_32"/>
    <exclude body1="B_32" body2="B_33"/>
    <exclude body1="B_33" body2="B_34"/>
    <exclude body1="B_34" body2="B_35"/>
    <exclude body1="B_35" body2="B_36"/>
    <exclude body1="B_36" body2="B_37"/>
    <exclude body1="B_37" body2="B_38"/>
    <exclude body1="B_38" body2="B_last"/>
  </contact>
  <equality>
    <weld body1="B_last" body2="eef_body" anchor="0 0 0" torquescale="1" relpose="0.23225 0 0 0 0 -1 0" solref="0.001"/>
    <weld body1="B_first" body2="eef_body2" anchor="0 0 0" torquescale="1" relpose="0 0 0 0 0 -1 0" solref="0.001"/>
  </equality>
</mujoco>
