<mujoco model="base">
  <compiler angle="radian"/>
  <option timestep="0.0015" tolerance="1e-10" integrator="implicit" cone="elliptic" jacobian="sparse" iterations="30"/>
  <size njmax="5000" nconmax="5000"/>
  <visual>
    <quality shadowsize="2048"/>
    <map stiffness="700" fogstart="10" fogend="15" znear="0.001" zfar="40" shadowscale="0.5"/>
    <rgba haze="0.15 0.25 0.35 1"/>
  </visual>
  <statistic meansize="0.05" extent="2"/>
  <asset>
    <texture type="skybox" builtin="gradient" rgb1="1 1 0.9" rgb2="0.9 0.9 0.81" width="512" height="3072"/>
    <texture type="2d" name="texplane" builtin="checker" mark="cross" rgb1="0.2 0.3 0.4" rgb2="0.1 0.15 0.2" markrgb="0.8 0.8 0.8" width="512" height="512"/>
    <material name="matplane" texture="texplane" texuniform="true" reflectance="0.3"/>
  </asset>
  <worldbody>
    <geom name="floor" size="3 3 0.125" pos="0 0 -10" type="plane" condim="1" material="matplane"/>
    <camera pos="0 -1 1.5" quat="0.866019 0.500011 0 0"/>
    <camera pos="1 -1.2 0.8" quat="0.687095 0.527073 0.304042 0.397055"/>
    <camera pos="-1.8 -1.1 0.7" quat="0.732963 0.562422 -0.232963 -0.303603"/>
    <camera pos="-1 -1.5 0.5" quat="0.707107 0.707107 0 0"/>
    <camera pos="9.7 -1 1.1" quat="0.687095 0.527073 0.304042 0.397055"/>
    <camera pos="4.5 -8 0.5" quat="0.707107 0.707107 0 0"/>
    <light pos="0 0 5" dir="0 0 -1" directional="true" castshadow="false" diffuse="0.4 0.4 0.4" specular="0.1 0.1 0.1"/>
    <light pos="0 0 4" dir="0 0 -1" directional="true" diffuse="0.6 0.6 0.6" specular="0.2 0.2 0.2"/>
    <body name="eef_body" pos="-4.645 0 0.5">
      <geom name="eef_geom" size="0.05 0.05 0.1" type="box" contype="0" conaffinity="0" mass="1" rgba="0.8 0.2 0.1 0"/>
    </body>
    <body name="eef_body2" pos="4.645 0 0.5">
      <geom name="eef_geom2" size="0.05 0.05 0.1" type="box" contype="0" conaffinity="0" mass="1" rgba="0.8 0.2 0.1 0"/>
    </body>
    <body name="stiffrope" pos="4.645 0 0.5" quat="0 0 1 0">
      <joint name="freejoint_A" type="free" limited="false" actuatorfrclimited="false"/>
      <site name="ft_rope" pos="0 0 0" size="0.05" group="1" rgba="1 0 0 0"/>
      <body name="B_first">
        <geom name="G0" size="0.025 0.0422" pos="0.0422273 0 0" quat="0.707107 0 -0.707107 0" type="capsule" contype="0" conaffinity="0" condim="1" rgba="0.1 0.0533333 0.673333 1"/>
        <site name="S_first" pos="0 0 0"/>
        <site name="S_0" pos="0 0 0"/>
        <site name="twistcylx_1" pos="0 0 0.05" quat="0.707107 0 0 -0.707107" size="0.001 0.05" group="1" type="cylinder" rgba="0 0 1 0"/>
        <site name="twistcyly_1" pos="0 0.05 0" quat="0.707107 -0.707107 0 0" size="0.001 0.05" group="1" type="cylinder" rgba="1 1 0 0"/>
        <body name="B_1" pos="0.0844545 0 0">
          <joint name="J_1" pos="0 0 0" type="ball" actuatorfrclimited="false" damping="1"/>
          <geom name="G1" size="0.025 0.0422" pos="0.0422273 0 0" quat="0.707107 0 -0.707107 0" type="capsule" contype="0" conaffinity="0" condim="1" rgba="0.1 0.0533333 0.673333 1"/>
          <site name="S_1" pos="0 0 0"/>
          <body name="B_2" pos="0.0844545 0 0">
            <joint name="J_2" pos="0 0 0" type="ball" actuatorfrclimited="false" damping="1"/>
            <geom name="G2" size="0.025 0.0422" pos="0.0422273 0 0" quat="0.707107 0 -0.707107 0" type="capsule" contype="0" conaffinity="0" condim="1" rgba="0.1 0.0533333 0.673333 1"/>
            <site name="S_2" pos="0 0 0"/>
            <body name="B_3" pos="0.0844545 0 0">
              <joint name="J_3" pos="0 0 0" type="ball" actuatorfrclimited="false" damping="1"/>
              <geom name="G3" size="0.025 0.0422" pos="0.0422273 0 0" quat="0.707107 0 -0.707107 0" type="capsule" contype="0" conaffinity="0" condim="1" rgba="0.1 0.0533333 0.673333 1"/>
              <site name="S_3" pos="0 0 0"/>
              <body name="B_4" pos="0.0844545 0 0">
                <joint name="J_4" pos="0 0 0" type="ball" actuatorfrclimited="false" damping="1"/>
                <geom name="G4" size="0.025 0.0422" pos="0.0422273 0 0" quat="0.707107 0 -0.707107 0" type="capsule" contype="0" conaffinity="0" condim="1" rgba="0.1 0.0533333 0.673333 1"/>
                <site name="S_4" pos="0 0 0"/>
                <body name="B_5" pos="0.0844545 0 0">
                  <joint name="J_5" pos="0 0 0" type="ball" actuatorfrclimited="false" damping="1"/>
                  <geom name="G5" size="0.025 0.0422" pos="0.0422273 0 0" quat="0.707107 0 -0.707107 0" type="capsule" contype="0" conaffinity="0" condim="1" rgba="0.1 0.0533333 0.673333 1"/>
                  <site name="S_5" pos="0 0 0"/>
                  <body name="B_6" pos="0.0844545 0 0">
                    <joint name="J_6" pos="0 0 0" type="ball" actuatorfrclimited="false" damping="1"/>
                    <geom name="G6" size="0.025 0.0422" pos="0.0422273 0 0" quat="0.707107 0 -0.707107 0" type="capsule" contype="0" conaffinity="0" condim="1" rgba="0.1 0.0533333 0.673333 1"/>
                    <site name="S_6" pos="0 0 0"/>
                    <body name="B_7" pos="0.0844545 0 0">
                      <joint name="J_7" pos="0 0 0" type="ball" actuatorfrclimited="false" damping="1"/>
                      <geom name="G7" size="0.025 0.0422" pos="0.0422273 0 0" quat="0.707107 0 -0.707107 0" type="capsule" contype="0" conaffinity="0" condim="1" rgba="0.1 0.0533333 0.673333 1"/>
                      <site name="S_7" pos="0 0 0"/>
                      <body name="B_8" pos="0.0844545 0 0">
                        <joint name="J_8" pos="0 0 0" type="ball" actuatorfrclimited="false" damping="1"/>
                        <geom name="G8" size="0.025 0.0422" pos="0.0422273 0 0" quat="0.707107 0 -0.707107 0" type="capsule" contype="0" conaffinity="0" condim="1" rgba="0.1 0.0533333 0.673333 1"/>
                        <site name="S_8" pos="0 0 0"/>
                        <body name="B_9" pos="0.0844545 0 0">
                          <joint name="J_9" pos="0 0 0" type="ball" actuatorfrclimited="false" damping="1"/>
                          <geom name="G9" size="0.025 0.0422" pos="0.0422273 0 0" quat="0.707107 0 -0.707107 0" type="capsule" contype="0" conaffinity="0" condim="1" rgba="0.1 0.0533333 0.673333 1"/>
                          <site name="S_9" pos="0 0 0"/>
                          <body name="B_10" pos="0.0844545 0 0">
                            <joint name="J_10" pos="0 0 0" type="ball" actuatorfrclimited="false" damping="1"/>
                            <geom name="G10" size="0.025 0.0422" pos="0.0422273 0 0" quat="0.707107 0 -0.707107 0" type="capsule" contype="0" conaffinity="0" condim="1" rgba="0.1 0.0533333 0.673333 1"/>
                            <site name="S_10" pos="0 0 0"/>
                            <body name="B_11" pos="0.0844545 0 0">
                              <joint name="J_11" pos="0 0 0" type="ball" actuatorfrclimited="false" damping="1"/>
                              <geom name="G11" size="0.025 0.0422" pos="0.0422273 0 0" quat="0.707107 0 -0.707107 0" type="capsule" contype="0" conaffinity="0" condim="1" rgba="0.1 0.0533333 0.673333 1"/>
                              <site name="S_11" pos="0 0 0"/>
                              <body name="B_12" pos="0.0844545 0 0">
                                <joint name="J_12" pos="0 0 0" type="ball" actuatorfrclimited="false" damping="1"/>
                                <geom name="G12" size="0.025 0.0422" pos="0.0422273 0 0" quat="0.707107 0 -0.707107 0" type="capsule" contype="0" conaffinity="0" condim="1" rgba="0.1 0.0533333 0.673333 1"/>
                                <site name="S_12" pos="0 0 0"/>
                                <body name="B_13" pos="0.0844545 0 0">
                                  <joint name="J_13" pos="0 0 0" type="ball" actuatorfrclimited="false" damping="1"/>
                                  <geom name="G13" size="0.025 0.0422" pos="0.0422273 0 0" quat="0.707107 0 -0.707107 0" type="capsule" contype="0" conaffinity="0" condim="1" rgba="0.1 0.0533333 0.673333 1"/>
                                  <site name="S_13" pos="0 0 0"/>
                                  <body name="B_14" pos="0.0844545 0 0">
                                    <joint name="J_14" pos="0 0 0" type="ball" actuatorfrclimited="false" damping="1"/>
                                    <geom name="G14" size="0.025 0.0422" pos="0.0422273 0 0" quat="0.707107 0 -0.707107 0" type="capsule" contype="0" conaffinity="0" condim="1" rgba="0.1 0.0533333 0.673333 1"/>
                                    <site name="S_14" pos="0 0 0"/>
                                    <body name="B_15" pos="0.0844545 0 0">
                                      <joint name="J_15" pos="0 0 0" type="ball" actuatorfrclimited="false" damping="1"/>
                                      <geom name="G15" size="0.025 0.0422" pos="0.0422273 0 0" quat="0.707107 0 -0.707107 0" type="capsule" contype="0" conaffinity="0" condim="1" rgba="0.1 0.0533333 0.673333 1"/>
                                      <site name="S_15" pos="0 0 0"/>
                                      <body name="B_16" pos="0.0844545 0 0">
                                        <joint name="J_16" pos="0 0 0" type="ball" actuatorfrclimited="false" damping="1"/>
                                        <geom name="G16" size="0.025 0.0422" pos="0.0422273 0 0" quat="0.707107 0 -0.707107 0" type="capsule" contype="0" conaffinity="0" condim="1" rgba="0.1 0.0533333 0.673333 1"/>
                                        <site name="S_16" pos="0 0 0"/>
                                        <body name="B_17" pos="0.0844545 0 0">
                                          <joint name="J_17" pos="0 0 0" type="ball" actuatorfrclimited="false" damping="1"/>
                                          <geom name="G17" size="0.025 0.0422" pos="0.0422273 0 0" quat="0.707107 0 -0.707107 0" type="capsule" contype="0" conaffinity="0" condim="1" rgba="0.1 0.0533333 0.673333 1"/>
                                          <site name="S_17" pos="0 0 0"/>
                                          <body name="B_18" pos="0.0844545 0 0">
                                            <joint name="J_18" pos="0 0 0" type="ball" actuatorfrclimited="false" damping="1"/>
                                            <geom name="G18" size="0.025 0.0422" pos="0.0422273 0 0" quat="0.707107 0 -0.707107 0" type="capsule" contype="0" conaffinity="0" condim="1" rgba="0.1 0.0533333 0.673333 1"/>
                                            <site name="S_18" pos="0 0 0"/>
                                            <body name="B_19" pos="0.0844545 0 0">
                                              <joint name="J_19" pos="0 0 0" type="ball" actuatorfrclimited="false" damping="1"/>
                                              <geom name="G19" size="0.025 0.0422" pos="0.0422273 0 0" quat="0.707107 0 -0.707107 0" type="capsule" contype="0" conaffinity="0" condim="1" rgba="0.1 0.0533333 0.673333 1"/>
                                              <site name="S_19" pos="0 0 0"/>
                                              <body name="B_20" pos="0.0844545 0 0">
                                                <joint name="J_20" pos="0 0 0" type="ball" actuatorfrclimited="false" damping="1"/>
                                                <geom name="G20" size="0.025 0.0422" pos="0.0422273 0 0" quat="0.707107 0 -0.707107 0" type="capsule" contype="0" conaffinity="0" condim="1" rgba="0.1 0.0533333 0.673333 1"/>
                                                <site name="S_20" pos="0 0 0"/>
                                                <body name="B_21" pos="0.0844545 0 0">
                                                  <joint name="J_21" pos="0 0 0" type="ball" actuatorfrclimited="false" damping="1"/>
                                                  <geom name="G21" size="0.025 0.0422" pos="0.0422273 0 0" quat="0.707107 0 -0.707107 0" type="capsule" contype="0" conaffinity="0" condim="1" rgba="0.1 0.0533333 0.673333 1"/>
                                                  <site name="S_21" pos="0 0 0"/>
                                                  <body name="B_22" pos="0.0844545 0 0">
                                                    <joint name="J_22" pos="0 0 0" type="ball" actuatorfrclimited="false" damping="1"/>
                                                    <geom name="G22" size="0.025 0.0422" pos="0.0422273 0 0" quat="0.707107 0 -0.707107 0" type="capsule" contype="0" conaffinity="0" condim="1" rgba="0.1 0.0533333 0.673333 1"/>
                                                    <site name="S_22" pos="0 0 0"/>
                                                    <body name="B_23" pos="0.0844545 0 0">
                                                      <joint name="J_23" pos="0 0 0" type="ball" actuatorfrclimited="false" damping="1"/>
                                                      <geom name="G23" size="0.025 0.0422" pos="0.0422273 0 0" quat="0.707107 0 -0.707107 0" type="capsule" contype="0" conaffinity="0" condim="1" rgba="0.1 0.0533333 0.673333 1"/>
                                                      <site name="S_23" pos="0 0 0"/>
                                                      <body name="B_24" pos="0.0844545 0 0">
                                                        <joint name="J_24" pos="0 0 0" type="ball" actuatorfrclimited="false" damping="1"/>
                                                        <geom name="G24" size="0.025 0.0422" pos="0.0422273 0 0" quat="0.707107 0 -0.707107 0" type="capsule" contype="0" conaffinity="0" condim="1" rgba="0.1 0.0533333 0.673333 1"/>
                                                        <site name="S_24" pos="0 0 0"/>
                                                        <body name="B_25" pos="0.0844545 0 0">
                                                          <joint name="J_25" pos="0 0 0" type="ball" actuatorfrclimited="false" damping="1"/>
                                                          <geom name="G25" size="0.025 0.0422" pos="0.0422273 0 0" quat="0.707107 0 -0.707107 0" type="capsule" contype="0" conaffinity="0" condim="1" rgba="0.1 0.0533333 0.673333 1"/>
                                                          <site name="S_25" pos="0 0 0"/>
                                                          <body name="B_26" pos="0.0844545 0 0">
                                                            <joint name="J_26" pos="0 0 0" type="ball" actuatorfrclimited="false" damping="1"/>
                                                            <geom name="G26" size="0.025 0.0422" pos="0.0422273 0 0" quat="0.707107 0 -0.707107 0" type="capsule" contype="0" conaffinity="0" condim="1" rgba="0.1 0.0533333 0.673333 1"/>
                                                            <site name="S_26" pos="0 0 0"/>
                                                            <body name="B_27" pos="0.0844545 0 0">
                                                              <joint name="J_27" pos="0 0 0" type="ball" actuatorfrclimited="false" damping="1"/>
                                                              <geom name="G27" size="0.025 0.0422" pos="0.0422273 0 0" quat="0.707107 0 -0.707107 0" type="capsule" contype="0" conaffinity="0" condim="1" rgba="0.1 0.0533333 0.673333 1"/>
                                                              <site name="S_27" pos="0 0 0"/>
                                                              <body name="B_28" pos="0.0844545 0 0">
                                                                <joint name="J_28" pos="0 0 0" type="ball" actuatorfrclimited="false" damping="1"/>
                                                                <geom name="G28" size="0.025 0.0422" pos="0.0422273 0 0" quat="0.707107 0 -0.707107 0" type="capsule" contype="0" conaffinity="0" condim="1" rgba="0.1 0.0533333 0.673333 1"/>
                                                                <site name="S_28" pos="0 0 0"/>
                                                                <body name="B_29" pos="0.0844545 0 0">
                                                                  <joint name="J_29" pos="0 0 0" type="ball" actuatorfrclimited="false" damping="1"/>
                                                                  <geom name="G29" size="0.025 0.0422" pos="0.0422273 0 0" quat="0.707107 0 -0.707107 0" type="capsule" contype="0" conaffinity="0" condim="1" rgba="0.1 0.0533333 0.673333 1"/>
                                                                  <site name="S_29" pos="0 0 0"/>
                                                                  <body name="B_30" pos="0.0844545 0 0">
                                                                    <joint name="J_30" pos="0 0 0" type="ball" actuatorfrclimited="false" damping="1"/>
                                                                    <geom name="G30" size="0.025 0.0422" pos="0.0422273 0 0" quat="0.707107 0 -0.707107 0" type="capsule" contype="0" conaffinity="0" condim="1" rgba="0.1 0.0533333 0.673333 1"/>
                                                                    <site name="S_30" pos="0 0 0"/>
                                                                    <body name="B_31" pos="0.0844545 0 0">
                                                                      <joint name="J_31" pos="0 0 0" type="ball" actuatorfrclimited="false" damping="1"/>
                                                                      <geom name="G31" size="0.025 0.0422" pos="0.0422273 0 0" quat="0.707107 0 -0.707107 0" type="capsule" contype="0" conaffinity="0" condim="1" rgba="0.1 0.0533333 0.673333 1"/>
                                                                      <site name="S_31" pos="0 0 0"/>
                                                                      <body name="B_32" pos="0.0844545 0 0">
                                                                        <joint name="J_32" pos="0 0 0" type="ball" actuatorfrclimited="false" damping="1"/>
                                                                        <geom name="G32" size="0.025 0.0422" pos="0.0422273 0 0" quat="0.707107 0 -0.707107 0" type="capsule" contype="0" conaffinity="0" condim="1" rgba="0.1 0.0533333 0.673333 1"/>
                                                                        <site name="S_32" pos="0 0 0"/>
                                                                        <body name="B_33" pos="0.0844545 0 0">
                                                                          <joint name="J_33" pos="0 0 0" type="ball" actuatorfrclimited="false" damping="1"/>
                                                                          <geom name="G33" size="0.025 0.0422" pos="0.0422273 0 0" quat="0.707107 0 -0.707107 0" type="capsule" contype="0" conaffinity="0" condim="1" rgba="0.1 0.0533333 0.673333 1"/>
                                                                          <site name="S_33" pos="0 0 0"/>
                                                                          <body name="B_34" pos="0.0844545 0 0">
                                                                            <joint name="J_34" pos="0 0 0" type="ball" actuatorfrclimited="false" damping="1"/>
                                                                            <geom name="G34" size="0.025 0.0422" pos="0.0422273 0 0" quat="0.707107 0 -0.707107 0" type="capsule" contype="0" conaffinity="0" condim="1" rgba="0.1 0.0533333 0.673333 1"/>
                                                                            <site name="S_34" pos="0 0 0"/>
                                                                            <body name="B_35" pos="0.0844545 0 0">
                                                                              <joint name="J_35" pos="0 0 0" type="ball" actuatorfrclimited="false" damping="1"/>
                                                                              <geom name="G35" size="0.025 0.0422" pos="0.0422273 0 0" quat="0.707107 0 -0.707107 0" type="capsule" contype="0" conaffinity="0" condim="1" rgba="0.1 0.0533333 0.673333 1"/>
                                                                              <site name="S_35" pos="0 0 0"/>
                                                                              <body name="B_36" pos="0.0844545 0 0">
                                                                                <joint name="J_36" pos="0 0 0" type="ball" actuatorfrclimited="false" damping="1"/>
                                                                                <geom name="G36" size="0.025 0.0422" pos="0.0422273 0 0" quat="0.707107 0 -0.707107 0" type="capsule" contype="0" conaffinity="0" condim="1" rgba="0.1 0.0533333 0.673333 1"/>
                                                                                <site name="S_36" pos="0 0 0"/>
                                                                                <body name="B_37" pos="0.0844545 0 0">
                                                                                  <joint name="J_37" pos="0 0 0" type="ball" actuatorfrclimited="false" damping="1"/>
                                                                                  <geom name="G37" size="0.025 0.0422" pos="0.0422273 0 0" quat="0.707107 0 -0.707107 0" type="capsule" contype="0" conaffinity="0" condim="1" rgba="0.1 0.0533333 0.673333 1"/>
                                                                                  <site name="S_37" pos="0 0 0"/>
                                                                                  <body name="B_38" pos="0.0844545 0 0">
                                                                                    <joint name="J_38" pos="0 0 0" type="ball" actuatorfrclimited="false" damping="1"/>
                                                                                    <geom name="G38" size="0.025 0.0422" pos="0.0422273 0 0" quat="0.707107 0 -0.707107 0" type="capsule" contype="0" conaffinity="0" condim="1" rgba="0.1 0.0533333 0.673333 1"/>
                                                                                    <site name="S_38" pos="0 0 0"/>
                                                                                    <body name="B_39" pos="0.0844545 0 0">
                                                                                      <joint name="J_39" pos="0 0 0" type="ball" actuatorfrclimited="false" damping="1"/>
                                                                                      <geom name="G39" size="0.025 0.0422" pos="0.0422273 0 0" quat="0.707107 0 -0.707107 0" type="capsule" contype="0" conaffinity="0" condim="1" rgba="0.1 0.0533333 0.673333 1"/>
                                                                                      <site name="S_39" pos="0 0 0"/>
                                                                                      <body name="B_40" pos="0.0844545 0 0">
                                                                                        <joint name="J_40" pos="0 0 0" type="ball" actuatorfrclimited="false" damping="1"/>
                                                                                        <geom name="G40" size="0.025 0.0422" pos="0.0422273 0 0" quat="0.707107 0 -0.707107 0" type="capsule" contype="0" conaffinity="0" condim="1" rgba="0.1 0.0533333 0.673333 1"/>
                                                                                        <site name="S_40" pos="0 0 0"/>
                                                                                        <body name="B_41" pos="0.0844545 0 0">
                                                                                          <joint name="J_41" pos="0 0 0" type="ball" actuatorfrclimited="false" damping="1"/>
                                                                                          <geom name="G41" size="0.025 0.0422" pos="0.0422273 0 0" quat="0.707107 0 -0.707107 0" type="capsule" contype="0" conaffinity="0" condim="1" rgba="0.1 0.0533333 0.673333 1"/>
                                                                                          <site name="S_41" pos="0 0 0"/>
                                                                                          <body name="B_42" pos="0.0844545 0 0">
                                                                                            <joint name="J_42" pos="0 0 0" type="ball" actuatorfrclimited="false" damping="1"/>
                                                                                            <geom name="G42" size="0.025 0.0422" pos="0.0422273 0 0" quat="0.707107 0 -0.707107 0" type="capsule" contype="0" conaffinity="0" condim="1" rgba="0.1 0.0533333 0.673333 1"/>
                                                                                            <site name="S_42" pos="0 0 0"/>
                                                                                            <body name="B_43" pos="0.0844545 0 0">
                                                                                              <joint name="J_43" pos="0 0 0" type="ball" actuatorfrclimited="false" damping="1"/>
                                                                                              <geom name="G43" size="0.025 0.0422" pos="0.0422273 0 0" quat="0.707107 0 -0.707107 0" type="capsule" contype="0" conaffinity="0" condim="1" rgba="0.1 0.0533333 0.673333 1"/>
                                                                                              <site name="S_43" pos="0 0 0"/>
                                                                                              <body name="B_44" pos="0.0844545 0 0">
                                                                                                <joint name="J_44" pos="0 0 0" type="ball" actuatorfrclimited="false" damping="1"/>
                                                                                                <geom name="G44" size="0.025 0.0422" pos="0.0422273 0 0" quat="0.707107 0 -0.707107 0" type="capsule" contype="0" conaffinity="0" condim="1" rgba="0.1 0.0533333 0.673333 1"/>
                                                                                                <site name="S_44" pos="0 0 0"/>
                                                                                                <body name="B_45" pos="0.0844545 0 0">
                                                                                                  <joint name="J_45" pos="0 0 0" type="ball" actuatorfrclimited="false" damping="1"/>
                                                                                                  <geom name="G45" size="0.025 0.0422" pos="0.0422273 0 0" quat="0.707107 0 -0.707107 0" type="capsule" contype="0" conaffinity="0" condim="1" rgba="0.1 0.0533333 0.673333 1"/>
                                                                                                  <site name="S_45" pos="0 0 0"/>
                                                                                                  <body name="B_46" pos="0.0844545 0 0">
                                                                                                    <joint name="J_46" pos="0 0 0" type="ball" actuatorfrclimited="false" damping="1"/>
                                                                                                    <geom name="G46" size="0.025 0.0422" pos="0.0422273 0 0" quat="0.707107 0 -0.707107 0" type="capsule" contype="0" conaffinity="0" condim="1" rgba="0.1 0.0533333 0.673333 1"/>
                                                                                                    <site name="S_46" pos="0 0 0"/>
                                                                                                    <body name="B_47" pos="0.0844545 0 0">
                                                                                                      <joint name="J_47" pos="0 0 0" type="ball" actuatorfrclimited="false" damping="1"/>
                                                                                                      <geom name="G47" size="0.025 0.0422" pos="0.0422273 0 0" quat="0.707107 0 -0.707107 0" type="capsule" contype="0" conaffinity="0" condim="1" rgba="0.1 0.0533333 0.673333 1"/>
                                                                                                      <site name="S_47" pos="0 0 0"/>
                                                                                                      <body name="B_48" pos="0.0844545 0 0">
                                                                                                        <joint name="J_48" pos="0 0 0" type="ball" actuatorfrclimited="false" damping="1"/>
                                                                                                        <geom name="G48" size="0.025 0.0422" pos="0.0422273 0 0" quat="0.707107 0 -0.707107 0" type="capsule" contype="0" conaffinity="0" condim="1" rgba="0.1 0.0533333 0.673333 1"/>
                                                                                                        <site name="S_48" pos="0 0 0"/>
                                                                                                        <body name="B_49" pos="0.0844545 0 0">
                                                                                                          <joint name="J_49" pos="0 0 0" type="ball" actuatorfrclimited="false" damping="1"/>
                                                                                                          <geom name="G49" size="0.025 0.0422" pos="0.0422273 0 0" quat="0.707107 0 -0.707107 0" type="capsule" contype="0" conaffinity="0" condim="1" rgba="0.1 0.0533333 0.673333 1"/>
                                                                                                          <site name="S_49" pos="0 0 0"/>
                                                                                                          <body name="B_50" pos="0.0844545 0 0">
                                                                                                            <joint name="J_50" pos="0 0 0" type="ball" actuatorfrclimited="false" damping="1"/>
                                                                                                            <geom name="G50" size="0.025 0.0422" pos="0.0422273 0 0" quat="0.707107 0 -0.707107 0" type="capsule" contype="0" conaffinity="0" condim="1" rgba="0.1 0.0533333 0.673333 1"/>
                                                                                                            <site name="S_50" pos="0 0 0"/>
                                                                                                            <body name="B_51" pos="0.0844545 0 0">
                                                                                                              <joint name="J_51" pos="0 0 0" type="ball" actuatorfrclimited="false" damping="1"/>
                                                                                                              <geom name="G51" size="0.025 0.0422" pos="0.0422273 0 0" quat="0.707107 0 -0.707107 0" type="capsule" contype="0" conaffinity="0" condim="1" rgba="0.1 0.0533333 0.673333 1"/>
                                                                                                              <site name="S_51" pos="0 0 0"/>
                                                                                                              <body name="B_52" pos="0.0844545 0 0">
                                                                                                                <joint name="J_52" pos="0 0 0" type="ball" actuatorfrclimited="false" damping="1"/>
                                                                                                                <geom name="G52" size="0.025 0.0422" pos="0.0422273 0 0" quat="0.707107 0 -0.707107 0" type="capsule" contype="0" conaffinity="0" condim="1" rgba="0.1 0.0533333 0.673333 1"/>
                                                                                                                <site name="S_52" pos="0 0 0"/>
                                                                                                                <body name="B_53" pos="0.0844545 0 0">
                                                                                                                  <joint name="J_53" pos="0 0 0" type="ball" actuatorfrclimited="false" damping="1"/>
                                                                                                                  <geom name="G53" size="0.025 0.0422" pos="0.0422273 0 0" quat="0.707107 0 -0.707107 0" type="capsule" contype="0" conaffinity="0" condim="1" rgba="0.1 0.0533333 0.673333 1"/>
                                                                                                                  <site name="S_53" pos="0 0 0"/>
                                                                                                                  <body name="B_54" pos="0.0844545 0 0">
                                                                                                                    <joint name="J_54" pos="0 0 0" type="ball" actuatorfrclimited="false" damping="1"/>
                                                                                                                    <geom name="G54" size="0.025 0.0422" pos="0.0422273 0 0" quat="0.707107 0 -0.707107 0" type="capsule" contype="0" conaffinity="0" condim="1" rgba="0.1 0.0533333 0.673333 1"/>
                                                                                                                    <site name="S_54" pos="0 0 0"/>
                                                                                                                    <body name="B_55" pos="0.0844545 0 0">
                                                                                                                      <joint name="J_55" pos="0 0 0" type="ball" actuatorfrclimited="false" damping="1"/>
                                                                                                                      <geom name="G55" size="0.025 0.0422" pos="0.0422273 0 0" quat="0.707107 0 -0.707107 0" type="capsule" contype="0" conaffinity="0" condim="1" rgba="0.1 0.0533333 0.673333 1"/>
                                                                                                                      <site name="S_55" pos="0 0 0"/>
                                                                                                                      <site name="twistcylx_56" pos="0 0 0.05" quat="0.707107 0 0 -0.707107" size="0.001 0.05" group="1" type="cylinder" rgba="0 0 1 0"/>
                                                                                                                      <site name="twistcyly_56" pos="0 0.05 0" quat="0.707107 -0.707107 0 0" size="0.001 0.05" group="1" type="cylinder" rgba="1 1 0 0"/>
                                                                                                                      <body name="B_56" pos="0.0844545 0 0">
                                                                                                                        <joint name="J_56" pos="0 0 0" type="ball" actuatorfrclimited="false" damping="1"/>
                                                                                                                        <geom name="G56" size="0.025 0.0422" pos="0.0422273 0 0" quat="0.707107 0 -0.707107 0" type="capsule" contype="0" conaffinity="0" condim="1" rgba="0.1 0.0533333 0.673333 1"/>
                                                                                                                        <site name="S_56" pos="0 0 0"/>
                                                                                                                        <body name="B_57" pos="0.0844545 0 0">
                                                                                                                          <joint name="J_57" pos="0 0 0" type="ball" actuatorfrclimited="false" damping="1"/>
                                                                                                                          <geom name="G57" size="0.025 0.0422" pos="0.0422273 0 0" quat="0.707107 0 -0.707107 0" type="capsule" contype="0" conaffinity="0" condim="1" rgba="0.1 0.0533333 0.673333 1"/>
                                                                                                                          <site name="S_57" pos="0 0 0"/>
                                                                                                                          <body name="B_58" pos="0.0844545 0 0">
                                                                                                                            <joint name="J_58" pos="0 0 0" type="ball" actuatorfrclimited="false" damping="1"/>
                                                                                                                            <geom name="G58" size="0.025 0.0422" pos="0.0422273 0 0" quat="0.707107 0 -0.707107 0" type="capsule" contype="0" conaffinity="0" condim="1" rgba="0.1 0.0533333 0.673333 1"/>
                                                                                                                            <site name="S_58" pos="0 0 0"/>
                                                                                                                            <body name="B_59" pos="0.0844545 0 0">
                                                                                                                              <joint name="J_59" pos="0 0 0" type="ball" actuatorfrclimited="false" damping="1"/>
                                                                                                                              <geom name="G59" size="0.025 0.0422" pos="0.0422273 0 0" quat="0.707107 0 -0.707107 0" type="capsule" contype="0" conaffinity="0" condim="1" rgba="0.1 0.0533333 0.673333 1"/>
                                                                                                                              <site name="S_59" pos="0 0 0"/>
                                                                                                                              <body name="B_60" pos="0.0844545 0 0">
                                                                                                                                <joint name="J_60" pos="0 0 0" type="ball" actuatorfrclimited="false" damping="1"/>
                                                                                                                                <geom name="G60" size="0.025 0.0422" pos="0.0422273 0 0" quat="0.707107 0 -0.707107 0" type="capsule" contype="0" conaffinity="0" condim="1" rgba="0.1 0.0533333 0.673333 1"/>
                                                                                                                                <site name="S_60" pos="0 0 0"/>
                                                                                                                                <body name="B_61" pos="0.0844545 0 0">
                                                                                                                                  <joint name="J_61" pos="0 0 0" type="ball" actuatorfrclimited="false" damping="1"/>
                                                                                                                                  <geom name="G61" size="0.025 0.0422" pos="0.0422273 0 0" quat="0.707107 0 -0.707107 0" type="capsule" contype="0" conaffinity="0" condim="1" rgba="0.1 0.0533333 0.673333 1"/>
                                                                                                                                  <site name="S_61" pos="0 0 0"/>
                                                                                                                                  <body name="B_62" pos="0.0844545 0 0">
                                                                                                                                    <joint name="J_62" pos="0 0 0" type="ball" actuatorfrclimited="false" damping="1"/>
                                                                                                                                    <geom name="G62" size="0.025 0.0422" pos="0.0422273 0 0" quat="0.707107 0 -0.707107 0" type="capsule" contype="0" conaffinity="0" condim="1" rgba="0.1 0.0533333 0.673333 1"/>
                                                                                                                                    <site name="S_62" pos="0 0 0"/>
                                                                                                                                    <body name="B_63" pos="0.0844545 0 0">
                                                                                                                                      <joint name="J_63" pos="0 0 0" type="ball" actuatorfrclimited="false" damping="1"/>
                                                                                                                                      <geom name="G63" size="0.025 0.0422" pos="0.0422273 0 0" quat="0.707107 0 -0.707107 0" type="capsule" contype="0" conaffinity="0" condim="1" rgba="0.1 0.0533333 0.673333 1"/>
                                                                                                                                      <site name="S_63" pos="0 0 0"/>
                                                                                                                                      <body name="B_64" pos="0.0844545 0 0">
                                                                                                                                        <joint name="J_64" pos="0 0 0" type="ball" actuatorfrclimited="false" damping="1"/>
                                                                                                                                        <geom name="G64" size="0.025 0.0422" pos="0.0422273 0 0" quat="0.707107 0 -0.707107 0" type="capsule" contype="0" conaffinity="0" condim="1" rgba="0.1 0.0533333 0.673333 1"/>
                                                                                                                                        <site name="S_64" pos="0 0 0"/>
                                                                                                                                        <body name="B_65" pos="0.0844545 0 0">
                                                                                                                                          <joint name="J_65" pos="0 0 0" type="ball" actuatorfrclimited="false" damping="1"/>
                                                                                                                                          <geom name="G65" size="0.025 0.0422" pos="0.0422273 0 0" quat="0.707107 0 -0.707107 0" type="capsule" contype="0" conaffinity="0" condim="1" rgba="0.1 0.0533333 0.673333 1"/>
                                                                                                                                          <site name="S_65" pos="0 0 0"/>
                                                                                                                                          <body name="B_66" pos="0.0844545 0 0">
                                                                                                                                            <joint name="J_66" pos="0 0 0" type="ball" actuatorfrclimited="false" damping="1"/>
                                                                                                                                            <geom name="G66" size="0.025 0.0422" pos="0.0422273 0 0" quat="0.707107 0 -0.707107 0" type="capsule" contype="0" conaffinity="0" condim="1" rgba="0.1 0.0533333 0.673333 1"/>
                                                                                                                                            <site name="S_66" pos="0 0 0"/>
                                                                                                                                            <body name="B_67" pos="0.0844545 0 0">
                                                                                                                                              <joint name="J_67" pos="0 0 0" type="ball" actuatorfrclimited="false" damping="1"/>
                                                                                                                                              <geom name="G67" size="0.025 0.0422" pos="0.0422273 0 0" quat="0.707107 0 -0.707107 0" type="capsule" contype="0" conaffinity="0" condim="1" rgba="0.1 0.0533333 0.673333 1"/>
                                                                                                                                              <site name="S_67" pos="0 0 0"/>
                                                                                                                                              <body name="B_68" pos="0.0844545 0 0">
                                                                                                                                                <joint name="J_68" pos="0 0 0" type="ball" actuatorfrclimited="false" damping="1"/>
                                                                                                                                                <geom name="G68" size="0.025 0.0422" pos="0.0422273 0 0" quat="0.707107 0 -0.707107 0" type="capsule" contype="0" conaffinity="0" condim="1" rgba="0.1 0.0533333 0.673333 1"/>
                                                                                                                                                <site name="S_68" pos="0 0 0"/>
                                                                                                                                                <body name="B_69" pos="0.0844545 0 0">
                                                                                                                                                  <joint name="J_69" pos="0 0 0" type="ball" actuatorfrclimited="false" damping="1"/>
                                                                                                                                                  <geom name="G69" size="0.025 0.0422" pos="0.0422273 0 0" quat="0.707107 0 -0.707107 0" type="capsule" contype="0" conaffinity="0" condim="1" rgba="0.1 0.0533333 0.673333 1"/>
                                                                                                                                                  <site name="S_69" pos="0 0 0"/>
                                                                                                                                                  <body name="B_70" pos="0.0844545 0 0">
                                                                                                                                                    <joint name="J_70" pos="0 0 0" type="ball" actuatorfrclimited="false" damping="1"/>
                                                                                                                                                    <geom name="G70" size="0.025 0.0422" pos="0.0422273 0 0" quat="0.707107 0 -0.707107 0" type="capsule" contype="0" conaffinity="0" condim="1" rgba="0.1 0.0533333 0.673333 1"/>
                                                                                                                                                    <site name="S_70" pos="0 0 0"/>
                                                                                                                                                    <body name="B_71" pos="0.0844545 0 0">
                                                                                                                                                      <joint name="J_71" pos="0 0 0" type="ball" actuatorfrclimited="false" damping="1"/>
                                                                                                                                                      <geom name="G71" size="0.025 0.0422" pos="0.0422273 0 0" quat="0.707107 0 -0.707107 0" type="capsule" contype="0" conaffinity="0" condim="1" rgba="0.1 0.0533333 0.673333 1"/>
                                                                                                                                                      <site name="S_71" pos="0 0 0"/>
                                                                                                                                                      <body name="B_72" pos="0.0844545 0 0">
                                                                                                                                                        <joint name="J_72" pos="0 0 0" type="ball" actuatorfrclimited="false" damping="1"/>
                                                                                                                                                        <geom name="G72" size="0.025 0.0422" pos="0.0422273 0 0" quat="0.707107 0 -0.707107 0" type="capsule" contype="0" conaffinity="0" condim="1" rgba="0.1 0.0533333 0.673333 1"/>
                                                                                                                                                        <site name="S_72" pos="0 0 0"/>
                                                                                                                                                        <body name="B_73" pos="0.0844545 0 0">
                                                                                                                                                          <joint name="J_73" pos="0 0 0" type="ball" actuatorfrclimited="false" damping="1"/>
                                                                                                                                                          <geom name="G73" size="0.025 0.0422" pos="0.0422273 0 0" quat="0.707107 0 -0.707107 0" type="capsule" contype="0" conaffinity="0" condim="1" rgba="0.1 0.0533333 0.673333 1"/>
                                                                                                                                                          <site name="S_73" pos="0 0 0"/>
                                                                                                                                                          <body name="B_74" pos="0.0844545 0 0">
                                                                                                                                                            <joint name="J_74" pos="0 0 0" type="ball" actuatorfrclimited="false" damping="1"/>
                                                                                                                                                            <geom name="G74" size="0.025 0.0422" pos="0.0422273 0 0" quat="0.707107 0 -0.707107 0" type="capsule" contype="0" conaffinity="0" condim="1" rgba="0.1 0.0533333 0.673333 1"/>
                                                                                                                                                            <site name="S_74" pos="0 0 0"/>
                                                                                                                                                            <body name="B_75" pos="0.0844545 0 0">
                                                                                                                                                              <joint name="J_75" pos="0 0 0" type="ball" actuatorfrclimited="false" damping="1"/>
                                                                                                                                                              <geom name="G75" size="0.025 0.0422" pos="0.0422273 0 0" quat="0.707107 0 -0.707107 0" type="capsule" contype="0" conaffinity="0" condim="1" rgba="0.1 0.0533333 0.673333 1"/>
                                                                                                                                                              <site name="S_75" pos="0 0 0"/>
                                                                                                                                                              <body name="B_76" pos="0.0844545 0 0">
                                                                                                                                                                <joint name="J_76" pos="0 0 0" type="ball" actuatorfrclimited="false" damping="1"/>
                                                                                                                                                                <geom name="G76" size="0.025 0.0422" pos="0.0422273 0 0" quat="0.707107 0 -0.707107 0" type="capsule" contype="0" conaffinity="0" condim="1" rgba="0.1 0.0533333 0.673333 1"/>
                                                                                                                                                                <site name="S_76" pos="0 0 0"/>
                                                                                                                                                                <body name="B_77" pos="0.0844545 0 0">
                                                                                                                                                                  <joint name="J_77" pos="0 0 0" type="ball" actuatorfrclimited="false" damping="1"/>
                                                                                                                                                                  <geom name="G77" size="0.025 0.0422" pos="0.0422273 0 0" quat="0.707107 0 -0.707107 0" type="capsule" contype="0" conaffinity="0" condim="1" rgba="0.1 0.0533333 0.673333 1"/>
                                                                                                                                                                  <site name="S_77" pos="0 0 0"/>
                                                                                                                                                                  <body name="B_78" pos="0.0844545 0 0">
                                                                                                                                                                    <joint name="J_78" pos="0 0 0" type="ball" actuatorfrclimited="false" damping="1"/>
                                                                                                                                                                    <geom name="G78" size="0.025 0.0422" pos="0.0422273 0 0" quat="0.707107 0 -0.707107 0" type="capsule" contype="0" conaffinity="0" condim="1" rgba="0.1 0.0533333 0.673333 1"/>
                                                                                                                                                                    <site name="S_78" pos="0 0 0"/>
                                                                                                                                                                    <body name="B_79" pos="0.0844545 0 0">
                                                                                                                                                                      <joint name="J_79" pos="0 0 0" type="ball" actuatorfrclimited="false" damping="1"/>
                                                                                                                                                                      <geom name="G79" size="0.025 0.0422" pos="0.0422273 0 0" quat="0.707107 0 -0.707107 0" type="capsule" contype="0" conaffinity="0" condim="1" rgba="0.1 0.0533333 0.673333 1"/>
                                                                                                                                                                      <site name="S_79" pos="0 0 0"/>
                                                                                                                                                                      <body name="B_80" pos="0.0844545 0 0">
                                                                                                                                                                        <joint name="J_80" pos="0 0 0" type="ball" actuatorfrclimited="false" damping="1"/>
                                                                                                                                                                        <geom name="G80" size="0.025 0.0422" pos="0.0422273 0 0" quat="0.707107 0 -0.707107 0" type="capsule" contype="0" conaffinity="0" condim="1" rgba="0.1 0.0533333 0.673333 1"/>
                                                                                                                                                                        <site name="S_80" pos="0 0 0"/>
                                                                                                                                                                        <body name="B_81" pos="0.0844545 0 0">
                                                                                                                                                                          <joint name="J_81" pos="0 0 0" type="ball" actuatorfrclimited="false" damping="1"/>
                                                                                                                                                                          <geom name="G81" size="0.025 0.0422" pos="0.0422273 0 0" quat="0.707107 0 -0.707107 0" type="capsule" contype="0" conaffinity="0" condim="1" rgba="0.1 0.0533333 0.673333 1"/>
                                                                                                                                                                          <site name="S_81" pos="0 0 0"/>
                                                                                                                                                                          <body name="B_82" pos="0.0844545 0 0">
                                                                                                                                                                            <joint name="J_82" pos="0 0 0" type="ball" actuatorfrclimited="false" damping="1"/>
                                                                                                                                                                            <geom name="G82" size="0.025 0.0422" pos="0.0422273 0 0" quat="0.707107 0 -0.707107 0" type="capsule" contype="0" conaffinity="0" condim="1" rgba="0.1 0.0533333 0.673333 1"/>
                                                                                                                                                                            <site name="S_82" pos="0 0 0"/>
                                                                                                                                                                            <body name="B_83" pos="0.0844545 0 0">
                                                                                                                                                                              <joint name="J_83" pos="0 0 0" type="ball" actuatorfrclimited="false" damping="1"/>
                                                                                                                                                                              <geom name="G83" size="0.025 0.0422" pos="0.0422273 0 0" quat="0.707107 0 -0.707107 0" type="capsule" contype="0" conaffinity="0" condim="1" rgba="0.1 0.0533333 0.673333 1"/>
                                                                                                                                                                              <site name="S_83" pos="0 0 0"/>
                                                                                                                                                                              <body name="B_84" pos="0.0844545 0 0">
                                                                                                                                                                                <joint name="J_84" pos="0 0 0" type="ball" actuatorfrclimited="false" damping="1"/>
                                                                                                                                                                                <geom name="G84" size="0.025 0.0422" pos="0.0422273 0 0" quat="0.707107 0 -0.707107 0" type="capsule" contype="0" conaffinity="0" condim="1" rgba="0.1 0.0533333 0.673333 1"/>
                                                                                                                                                                                <site name="S_84" pos="0 0 0"/>
                                                                                                                                                                                <body name="B_85" pos="0.0844545 0 0">
                                                                                                                                                                                  <joint name="J_85" pos="0 0 0" type="ball" actuatorfrclimited="false" damping="1"/>
                                                                                                                                                                                  <geom name="G85" size="0.025 0.0422" pos="0.0422273 0 0" quat="0.707107 0 -0.707107 0" type="capsule" contype="0" conaffinity="0" condim="1" rgba="0.1 0.0533333 0.673333 1"/>
                                                                                                                                                                                  <site name="S_85" pos="0 0 0"/>
                                                                                                                                                                                  <body name="B_86" pos="0.0844545 0 0">
                                                                                                                                                                                    <joint name="J_86" pos="0 0 0" type="ball" actuatorfrclimited="false" damping="1"/>
                                                                                                                                                                                    <geom name="G86" size="0.025 0.0422" pos="0.0422273 0 0" quat="0.707107 0 -0.707107 0" type="capsule" contype="0" conaffinity="0" condim="1" rgba="0.1 0.0533333 0.673333 1"/>
                                                                                                                                                                                    <site name="S_86" pos="0 0 0"/>
                                                                                                                                                                                    <body name="B_87" pos="0.0844545 0 0">
                                                                                                                                                                                      <joint name="J_87" pos="0 0 0" type="ball" actuatorfrclimited="false" damping="1"/>
                                                                                                                                                                                      <geom name="G87" size="0.025 0.0422" pos="0.0422273 0 0" quat="0.707107 0 -0.707107 0" type="capsule" contype="0" conaffinity="0" condim="1" rgba="0.1 0.0533333 0.673333 1"/>
                                                                                                                                                                                      <site name="S_87" pos="0 0 0"/>
                                                                                                                                                                                      <body name="B_88" pos="0.0844545 0 0">
                                                                                                                                                                                        <joint name="J_88" pos="0 0 0" type="ball" actuatorfrclimited="false" damping="1"/>
                                                                                                                                                                                        <geom name="G88" size="0.025 0.0422" pos="0.0422273 0 0" quat="0.707107 0 -0.707107 0" type="capsule" contype="0" conaffinity="0" condim="1" rgba="0.1 0.0533333 0.673333 1"/>
                                                                                                                                                                                        <site name="S_88" pos="0 0 0"/>
                                                                                                                                                                                        <body name="B_89" pos="0.0844545 0 0">
                                                                                                                                                                                          <joint name="J_89" pos="0 0 0" type="ball" actuatorfrclimited="false" damping="1"/>
                                                                                                                                                                                          <geom name="G89" size="0.025 0.0422" pos="0.0422273 0 0" quat="0.707107 0 -0.707107 0" type="capsule" contype="0" conaffinity="0" condim="1" rgba="0.1 0.0533333 0.673333 1"/>
                                                                                                                                                                                          <site name="S_89" pos="0 0 0"/>
                                                                                                                                                                                          <body name="B_90" pos="0.0844545 0 0">
                                                                                                                                                                                            <joint name="J_90" pos="0 0 0" type="ball" actuatorfrclimited="false" damping="1"/>
                                                                                                                                                                                            <geom name="G90" size="0.025 0.0422" pos="0.0422273 0 0" quat="0.707107 0 -0.707107 0" type="capsule" contype="0" conaffinity="0" condim="1" rgba="0.1 0.0533333 0.673333 1"/>
                                                                                                                                                                                            <site name="S_90" pos="0 0 0"/>
                                                                                                                                                                                            <body name="B_91" pos="0.0844545 0 0">
                                                                                                                                                                                              <joint name="J_91" pos="0 0 0" type="ball" actuatorfrclimited="false" damping="1"/>
                                                                                                                                                                                              <geom name="G91" size="0.025 0.0422" pos="0.0422273 0 0" quat="0.707107 0 -0.707107 0" type="capsule" contype="0" conaffinity="0" condim="1" rgba="0.1 0.0533333 0.673333 1"/>
                                                                                                                                                                                              <site name="S_91" pos="0 0 0"/>
                                                                                                                                                                                              <body name="B_92" pos="0.0844545 0 0">
                                                                                                                                                                                                <joint name="J_92" pos="0 0 0" type="ball" actuatorfrclimited="false" damping="1"/>
                                                                                                                                                                                                <geom name="G92" size="0.025 0.0422" pos="0.0422273 0 0" quat="0.707107 0 -0.707107 0" type="capsule" contype="0" conaffinity="0" condim="1" rgba="0.1 0.0533333 0.673333 1"/>
                                                                                                                                                                                                <site name="S_92" pos="0 0 0"/>
                                                                                                                                                                                                <body name="B_93" pos="0.0844545 0 0">
                                                                                                                                                                                                  <joint name="J_93" pos="0 0 0" type="ball" actuatorfrclimited="false" damping="1"/>
                                                                                                                                                                                                  <geom name="G93" size="0.025 0.0422" pos="0.0422273 0 0" quat="0.707107 0 -0.707107 0" type="capsule" contype="0" conaffinity="0" condim="1" rgba="0.1 0.0533333 0.673333 1"/>
                                                                                                                                                                                                  <site name="S_93" pos="0 0 0"/>
                                                                                                                                                                                                  <body name="B_94" pos="0.0844545 0 0">
                                                                                                                                                                                                    <joint name="J_94" pos="0 0 0" type="ball" actuatorfrclimited="false" damping="1"/>
                                                                                                                                                                                                    <geom name="G94" size="0.025 0.0422" pos="0.0422273 0 0" quat="0.707107 0 -0.707107 0" type="capsule" contype="0" conaffinity="0" condim="1" rgba="0.1 0.0533333 0.673333 1"/>
                                                                                                                                                                                                    <site name="S_94" pos="0 0 0"/>
                                                                                                                                                                                                    <body name="B_95" pos="0.0844545 0 0">
                                                                                                                                                                                                      <joint name="J_95" pos="0 0 0" type="ball" actuatorfrclimited="false" damping="1"/>
                                                                                                                                                                                                      <geom name="G95" size="0.025 0.0422" pos="0.0422273 0 0" quat="0.707107 0 -0.707107 0" type="capsule" contype="0" conaffinity="0" condim="1" rgba="0.1 0.0533333 0.673333 1"/>
                                                                                                                                                                                                      <site name="S_95" pos="0 0 0"/>
                                                                                                                                                                                                      <body name="B_96" pos="0.0844545 0 0">
                                                                                                                                                                                                        <joint name="J_96" pos="0 0 0" type="ball" actuatorfrclimited="false" damping="1"/>
                                                                                                                                                                                                        <geom name="G96" size="0.025 0.0422" pos="0.0422273 0 0" quat="0.707107 0 -0.707107 0" type="capsule" contype="0" conaffinity="0" condim="1" rgba="0.1 0.0533333 0.673333 1"/>
                                                                                                                                                                                                        <site name="S_96" pos="0 0 0"/>
                                                                                                                                                                                                        <body name="B_97" pos="0.0844545 0 0">
                                                                                                                                                                                                          <joint name="J_97" pos="0 0 0" type="ball" actuatorfrclimited="false" damping="1"/>
                                                                                                                                                                                                          <geom name="G97" size="0.025 0.0422" pos="0.0422273 0 0" quat="0.707107 0 -0.707107 0" type="capsule" contype="0" conaffinity="0" condim="1" rgba="0.1 0.0533333 0.673333 1"/>
                                                                                                                                                                                                          <site name="S_97" pos="0 0 0"/>
                                                                                                                                                                                                          <body name="B_98" pos="0.0844545 0 0">
                                                                                                                                                                                                            <joint name="J_98" pos="0 0 0" type="ball" actuatorfrclimited="false" damping="1"/>
                                                                                                                                                                                                            <geom name="G98" size="0.025 0.0422" pos="0.0422273 0 0" quat="0.707107 0 -0.707107 0" type="capsule" contype="0" conaffinity="0" condim="1" rgba="0.1 0.0533333 0.673333 1"/>
                                                                                                                                                                                                            <site name="S_98" pos="0 0 0"/>
                                                                                                                                                                                                            <body name="B_99" pos="0.0844545 0 0">
                                                                                                                                                                                                              <joint name="J_99" pos="0 0 0" type="ball" actuatorfrclimited="false" damping="1"/>
                                                                                                                                                                                                              <geom name="G99" size="0.025 0.0422" pos="0.0422273 0 0" quat="0.707107 0 -0.707107 0" type="capsule" contype="0" conaffinity="0" condim="1" rgba="0.1 0.0533333 0.673333 1"/>
                                                                                                                                                                                                              <site name="S_99" pos="0 0 0"/>
                                                                                                                                                                                                              <body name="B_100" pos="0.0844545 0 0">
                                                                                                                                                                                                                <joint name="J_100" pos="0 0 0" type="ball" actuatorfrclimited="false" damping="1"/>
                                                                                                                                                                                                                <geom name="G100" size="0.025 0.0422" pos="0.0422273 0 0" quat="0.707107 0 -0.707107 0" type="capsule" contype="0" conaffinity="0" condim="1" rgba="0.1 0.0533333 0.673333 1"/>
                                                                                                                                                                                                                <site name="S_100" pos="0 0 0"/>
                                                                                                                                                                                                                <body name="B_101" pos="0.0844545 0 0">
                                                                                                                                                                                                                  <joint name="J_101" pos="0 0 0" type="ball" actuatorfrclimited="false" damping="1"/>
                                                                                                                                                                                                                  <geom name="G101" size="0.025 0.0422" pos="0.0422273 0 0" quat="0.707107 0 -0.707107 0" type="capsule" contype="0" conaffinity="0" condim="1" rgba="0.1 0.0533333 0.673333 1"/>
                                                                                                                                                                                                                  <site name="S_101" pos="0 0 0"/>
                                                                                                                                                                                                                  <body name="B_102" pos="0.0844545 0 0">
                                                                                                                                                                                                                    <joint name="J_102" pos="0 0 0" type="ball" actuatorfrclimited="false" damping="1"/>
                                                                                                                                                                                                                    <geom name="G102" size="0.025 0.0422" pos="0.0422273 0 0" quat="0.707107 0 -0.707107 0" type="capsule" contype="0" conaffinity="0" condim="1" rgba="0.1 0.0533333 0.673333 1"/>
                                                                                                                                                                                                                    <site name="S_102" pos="0 0 0"/>
                                                                                                                                                                                                                    <body name="B_103" pos="0.0844545 0 0">
                                                                                                                                                                                                                      <joint name="J_103" pos="0 0 0" type="ball" actuatorfrclimited="false" damping="1"/>
                                                                                                                                                                                                                      <geom name="G103" size="0.025 0.0422" pos="0.0422273 0 0" quat="0.707107 0 -0.707107 0" type="capsule" contype="0" conaffinity="0" condim="1" rgba="0.1 0.0533333 0.673333 1"/>
                                                                                                                                                                                                                      <site name="S_103" pos="0 0 0"/>
                                                                                                                                                                                                                      <body name="B_104" pos="0.0844545 0 0">
                                                                                                                                                                                                                        <joint name="J_104" pos="0 0 0" type="ball" actuatorfrclimited="false" damping="1"/>
                                                                                                                                                                                                                        <geom name="G104" size="0.025 0.0422" pos="0.0422273 0 0" quat="0.707107 0 -0.707107 0" type="capsule" contype="0" conaffinity="0" condim="1" rgba="0.1 0.0533333 0.673333 1"/>
                                                                                                                                                                                                                        <site name="S_104" pos="0 0 0"/>
                                                                                                                                                                                                                        <body name="B_105" pos="0.0844545 0 0">
                                                                                                                                                                                                                          <joint name="J_105" pos="0 0 0" type="ball" actuatorfrclimited="false" damping="1"/>
                                                                                                                                                                                                                          <geom name="G105" size="0.025 0.0422" pos="0.0422273 0 0" quat="0.707107 0 -0.707107 0" type="capsule" contype="0" conaffinity="0" condim="1" rgba="0.1 0.0533333 0.673333 1"/>
                                                                                                                                                                                                                          <site name="S_105" pos="0 0 0"/>
                                                                                                                                                                                                                          <body name="B_106" pos="0.0844545 0 0">
                                                                                                                                                                                                                            <joint name="J_106" pos="0 0 0" type="ball" actuatorfrclimited="false" damping="1"/>
                                                                                                                                                                                                                            <geom name="G106" size="0.025 0.0422" pos="0.0422273 0 0" quat="0.707107 0 -0.707107 0" type="capsule" contype="0" conaffinity="0" condim="1" rgba="0.1 0.0533333 0.673333 1"/>
                                                                                                                                                                                                                            <site name="S_106" pos="0 0 0"/>
                                                                                                                                                                                                                            <body name="B_107" pos="0.0844545 0 0">
                                                                                                                                                                                                                              <joint name="J_107" pos="0 0 0" type="ball" actuatorfrclimited="false" damping="1"/>
                                                                                                                                                                                                                              <geom name="G107" size="0.025 0.0422" pos="0.0422273 0 0" quat="0.707107 0 -0.707107 0" type="capsule" contype="0" conaffinity="0" condim="1" rgba="0.1 0.0533333 0.673333 1"/>
                                                                                                                                                                                                                              <site name="S_107" pos="0 0 0"/>
                                                                                                                                                                                                                              <body name="B_108" pos="0.0844545 0 0">
                                                                                                                                                                                                                                <joint name="J_108" pos="0 0 0" type="ball" actuatorfrclimited="false" damping="1"/>
                                                                                                                                                                                                                                <geom name="G108" size="0.025 0.0422" pos="0.0422273 0 0" quat="0.707107 0 -0.707107 0" type="capsule" contype="0" conaffinity="0" condim="1" rgba="0.1 0.0533333 0.673333 1"/>
                                                                                                                                                                                                                                <site name="S_108" pos="0 0 0"/>
                                                                                                                                                                                                                                <body name="B_last" pos="0.0844545 0 0">
                                                                                                                                                                                                                                  <joint name="J_last" pos="0 0 0" type="ball" actuatorfrclimited="false" damping="1"/>
                                                                                                                                                                                                                                  <geom name="G109" size="0.025 0.0422" pos="0.0422273 0 0" quat="0.707107 0 -0.707107 0" type="capsule" contype="0" conaffinity="0" condim="1" rgba="0.1 0.0533333 0.673333 1"/>
                                                                                                                                                                                                                                  <site name="S_109" pos="0 0 0"/>
                                                                                                                                                                                                                                  <site name="twistcylx_110" pos="0 0 0.05" quat="0.707107 0 0 -0.707107" size="0.001 0.05" group="1" type="cylinder" rgba="0 0 1 0"/>
                                                                                                                                                                                                                                  <site name="twistcyly_110" pos="0 0.05 0" quat="0.707107 -0.707107 0 0" size="0.001 0.05" group="1" type="cylinder" rgba="1 1 0 0"/>
                                                                                                                                                                                                                                  <site name="S_last" pos="0.0844545 0 0"/>
                                                                                                                                                                                                                                  <body name="B_last2" pos="0.0844545 0 0"/>
                                                                                                                                                                                                                                </body>
                                                                                                                                                                                                                              </body>
                                                                                                                                                                                                                            </body>
                                                                                                                                                                                                                          </body>
                                                                                                                                                                                                                        </body>
                                                                                                                                                                                                                      </body>
                                                                                                                                                                                                                    </body>
                                                                                                                                                                                                                  </body>
                                                                                                                                                                                                                </body>
                                                                                                                                                                                                              </body>
                                                                                                                                                                                                            </body>
                                                                                                                                                                                                          </body>
                                                                                                                                                                                                        </body>
                                                                                                                                                                                                      </body>
                                                                                                                                                                                                    </body>
                                                                                                                                                                                                  </body>
                                                                                                                                                                                                </body>
                                                                                                                                                                                              </body>
                                                                                                                                                                                            </body>
                                                                                                                                                                                          </body>
                                                                                                                                                                                        </body>
                                                                                                                                                                                      </body>
                                                                                                                                                                                    </body>
                                                                                                                                                                                  </body>
                                                                                                                                                                                </body>
                                                                                                                                                                              </body>
                                                                                                                                                                            </body>
                                                                                                                                                                          </body>
                                                                                                                                                                        </body>
                                                                                                                                                                      </body>
                                                                                                                                                                    </body>
                                                                                                                                                                  </body>
                                                                                                                                                                </body>
                                                                                                                                                              </body>
                                                                                                                                                            </body>
                                                                                                                                                          </body>
                                                                                                                                                        </body>
                                                                                                                                                      </body>
                                                                                                                                                    </body>
                                                                                                                                                  </body>
                                                                                                                                                </body>
                                                                                                                                              </body>
                                                                                                                                            </body>
                                                                                                                                          </body>
                                                                                                                                        </body>
                                                                                                                                      </body>
                                                                                                                                    </body>
                                                                                                                                  </body>
                                                                                                                                </body>
                                                                                                                              </body>
                                                                                                                            </body>
                                                                                                                          </body>
                                                                                                                        </body>
                                                                                                                      </body>
                                                                                                                    </body>
                                                                                                                  </body>
                                                                                                                </body>
                                                                                                              </body>
                                                                                                            </body>
                                                                                                          </body>
                                                                                                        </body>
                                                                                                      </body>
                                                                                                    </body>
                                                                                                  </body>
                                                                                                </body>
                                                                                              </body>
                                                                                            </body>
                                                                                          </body>
                                                                                        </body>
                                                                                      </body>
                                                                                    </body>
                                                                                  </body>
                                                                                </body>
                                                                              </body>
                                                                            </body>
                                                                          </body>
                                                                        </body>
                                                                      </body>
                                                                    </body>
                                                                  </body>
                                                                </body>
                                                              </body>
                                                            </body>
                                                          </body>
                                                        </body>
                                                      </body>
                                                    </body>
                                                  </body>
                                                </body>
                                              </body>
                                            </body>
                                          </body>
                                        </body>
                                      </body>
                                    </body>
                                  </body>
                                </body>
                              </body>
                            </body>
                          </body>
                        </body>
                      </body>
                    </body>
                  </body>
                </body>
              </body>
            </body>
          </body>
        </body>
      </body>
    </body>
  </worldbody>
  <contact>
    <exclude body1="eef_body" body2="B_first"/>
    <exclude body1="eef_body" body2="B_108"/>
    <exclude body1="eef_body" body2="B_last"/>
    <exclude body1="B_first" body2="B_1"/>
    <exclude body1="B_first" body2="B_108"/>
    <exclude body1="B_first" body2="B_last"/>
    <exclude body1="B_1" body2="B_2"/>
    <exclude body1="B_1" body2="B_last"/>
    <exclude body1="B_2" body2="B_3"/>
    <exclude body1="B_3" body2="B_4"/>
    <exclude body1="B_4" body2="B_5"/>
    <exclude body1="B_5" body2="B_6"/>
    <exclude body1="B_6" body2="B_7"/>
    <exclude body1="B_7" body2="B_8"/>
    <exclude body1="B_8" body2="B_9"/>
    <exclude body1="B_9" body2="B_10"/>
    <exclude body1="B_10" body2="B_11"/>
    <exclude body1="B_11" body2="B_12"/>
    <exclude body1="B_12" body2="B_13"/>
    <exclude body1="B_13" body2="B_14"/>
    <exclude body1="B_14" body2="B_15"/>
    <exclude body1="B_15" body2="B_16"/>
    <exclude body1="B_16" body2="B_17"/>
    <exclude body1="B_17" body2="B_18"/>
    <exclude body1="B_18" body2="B_19"/>
    <exclude body1="B_19" body2="B_20"/>
    <exclude body1="B_20" body2="B_21"/>
    <exclude body1="B_21" body2="B_22"/>
    <exclude body1="B_22" body2="B_23"/>
    <exclude body1="B_23" body2="B_24"/>
    <exclude body1="B_24" body2="B_25"/>
    <exclude body1="B_25" body2="B_26"/>
    <exclude body1="B_26" body2="B_27"/>
    <exclude body1="B_27" body2="B_28"/>
    <exclude body1="B_28" body2="B_29"/>
    <exclude body1="B_29" body2="B_30"/>
    <exclude body1="B_30" body2="B_31"/>
    <exclude body1="B_31" body2="B_32"/>
    <exclude body1="B_32" body2="B_33"/>
    <exclude body1="B_33" body2="B_34"/>
    <exclude body1="B_34" body2="B_35"/>
    <exclude body1="B_35" body2="B_36"/>
    <exclude body1="B_36" body2="B_37"/>
    <exclude body1="B_37" body2="B_38"/>
    <exclude body1="B_38" body2="B_39"/>
    <exclude body1="B_39" body2="B_40"/>
    <exclude body1="B_40" body2="B_41"/>
    <exclude body1="B_41" body2="B_42"/>
    <exclude body1="B_42" body2="B_43"/>
    <exclude body1="B_43" body2="B_44"/>
    <exclude body1="B_44" body2="B_45"/>
    <exclude body1="B_45" body2="B_46"/>
    <exclude body1="B_46" body2="B_47"/>
    <exclude body1="B_47" body2="B_48"/>
    <exclude body1="B_48" body2="B_49"/>
    <exclude body1="B_49" body2="B_50"/>
    <exclude body1="B_50" body2="B_51"/>
    <exclude body1="B_51" body2="B_52"/>
    <exclude body1="B_52" body2="B_53"/>
    <exclude body1="B_53" body2="B_54"/>
    <exclude body1="B_54" body2="B_55"/>
    <exclude body1="B_55" body2="B_56"/>
    <exclude body1="B_56" body2="B_57"/>
    <exclude body1="B_57" body2="B_58"/>
    <exclude body1="B_58" body2="B_59"/>
    <exclude body1="B_59" body2="B_60"/>
    <exclude body1="B_60" body2="B_61"/>
    <exclude body1="B_61" body2="B_62"/>
    <exclude body1="B_62" body2="B_63"/>
    <exclude body1="B_63" body2="B_64"/>
    <exclude body1="B_64" body2="B_65"/>
    <exclude body1="B_65" body2="B_66"/>
    <exclude body1="B_66" body2="B_67"/>
    <exclude body1="B_67" body2="B_68"/>
    <exclude body1="B_68" body2="B_69"/>
    <exclude body1="B_69" body2="B_70"/>
    <exclude body1="B_70" body2="B_71"/>
    <exclude body1="B_71" body2="B_72"/>
    <exclude body1="B_72" body2="B_73"/>
    <exclude body1="B_73" body2="B_74"/>
    <exclude body1="B_74" body2="B_75"/>
    <exclude body1="B_75" body2="B_76"/>
    <exclude body1="B_76" body2="B_77"/>
    <exclude body1="B_77" body2="B_78"/>
    <exclude body1="B_78" body2="B_79"/>
    <exclude body1="B_79" body2="B_80"/>
    <exclude body1="B_80" body2="B_81"/>
    <exclude body1="B_81" body2="B_82"/>
    <exclude body1="B_82" body2="B_83"/>
    <exclude body1="B_83" body2="B_84"/>
    <exclude body1="B_84" body2="B_85"/>
    <exclude body1="B_85" body2="B_86"/>
    <exclude body1="B_86" body2="B_87"/>
    <exclude body1="B_87" body2="B_88"/>
    <exclude body1="B_88" body2="B_89"/>
    <exclude body1="B_89" body2="B_90"/>
    <exclude body1="B_90" body2="B_91"/>
    <exclude body1="B_91" body2="B_92"/>
    <exclude body1="B_92" body2="B_93"/>
    <exclude body1="B_93" body2="B_94"/>
    <exclude body1="B_94" body2="B_95"/>
    <exclude body1="B_95" body2="B_96"/>
    <exclude body1="B_96" body2="B_97"/>
    <exclude body1="B_97" body2="B_98"/>
    <exclude body1="B_98" body2="B_99"/>
    <exclude body1="B_99" body2="B_100"/>
    <exclude body1="B_100" body2="B_101"/>
    <exclude body1="B_101" body2="B_102"/>
    <exclude body1="B_102" body2="B_103"/>
    <exclude body1="B_103" body2="B_104"/>
    <exclude body1="B_104" body2="B_105"/>
    <exclude body1="B_105" body2="B_106"/>
    <exclude body1="B_106" body2="B_107"/>
    <exclude body1="B_107" body2="B_108"/>
    <exclude body1="B_108" body2="B_last"/>
  </contact>
  <equality>
    <weld body1="B_last" body2="eef_body" anchor="0 0 0" torquescale="1" relpose="0.0844545 0 0 0 0 -1 0" solref="0.001"/>
    <weld body1="B_first" body2="eef_body2" anchor="0 0 0" torquescale="1" relpose="0 0 0 0 0 -1 0" solref="0.001"/>
  </equality>
</mujoco>
